Workbook

Sheet Ringkasan
A1: RINGKASAN HASIL - MENCARI AKAR PERSAMAAN ALJABAR
A2: Metode: Regula Falsi (False Position) | Toleransi = 0,001
A4: No | B4: Persamaan f(x) = 0 | C4: Interval [a, b] | D4: Akar (x) | E4: f(akar) | F4: Iterasi | G4: Keterangan
A5: 1 | B5: x^2 - 3x + 1 | C5: [0, 1] | D5: ='Soal 1'!D26 | E5: ='Soal 1'!G26 | F5: =IFERROR(MATCH(TRUE,'Soal 1'!J7:J26,0),"-")
A6: 2 | B6: tan(pi - x) - x | C6: [2, 2.1] | D6: ='Soal 2'!D26 | E6: ='Soal 2'!G26 | F6: =IFERROR(MATCH(TRUE,'Soal 2'!J7:J26,0),"-")
A7: 3 | B7: x^3 - x^2 - x + 1 | C7: [-1.5, -0.5] | D7: ='Soal 3'!D26 | E7: ='Soal 3'!G26 | F7: =IFERROR(MATCH(TRUE,'Soal 3'!J7:J26,0),"-")
A8: 4 | B8: (x - 5)^4 | C8: [4, 6] | D8: 5 | E8: 0 | F8: - | G8: Tidak ada perubahan tanda; akar rangkap x = 5 (analitis)
A9: 5 | B9: x^3 - 4x + 1 | C9: [0, 1] | D9: ='Soal 5'!D26 | E9: ='Soal 5'!G26 | F9: =IFERROR(MATCH(TRUE,'Soal 5'!J7:J26,0),"-")
A10: 6 | B10: x + cos x | C10: [-1, 0] | D10: ='Soal 6'!D26 | E10: ='Soal 6'!G26 | F10: =IFERROR(MATCH(TRUE,'Soal 6'!J7:J26,0),"-")
A11: 7 | B11: 2x - log x - 6 (log basis 10) | C11: [3, 3.5] | D11: ='Soal 7'!D26 | E11: ='Soal 7'!G26 | F11: =IFERROR(MATCH(TRUE,'Soal 7'!J7:J26,0),"-") | G11: Diasumsikan log basis 10
A12: 8 | B12: x^6 - x^4 - x^3 - 1 | C12: [1, 1.5] | D12: ='Soal 8'!D26 | E12: ='Soal 8'!G26 | F12: =IFERROR(MATCH(TRUE,'Soal 8'!J7:J26,0),"-")
A13: 9 | B13: x - e^(-x) | C13: [0, 1] | D13: ='Soal 9'!D26 | E13: ='Soal 9'!G26 | F13: =IFERROR(MATCH(TRUE,'Soal 9'!J7:J26,0),"-") | G13: Dibaca f(x) = x - e^(-x) (koreksi penulisan soal)
A14: 10 | B14: ln[(1 + x)/(1 - x^2)] | C14: [-0.5, 0.5] | D14: ='Soal 10'!D26 | E14: ='Soal 10'!G26 | F14: =IFERROR(MATCH(TRUE,'Soal 10'!J7:J26,0),"-") | G14: (1+x)/(1-x^2) = 1/(1-x); akar x = 0
A16: Catatan:
A17: 1. Tiap soal dihitung pada sheet 'Soal 1' s/d 'Soal 10' dengan tabel iterasi otomatis (formula hidup, bisa diubah interval/toleransinya).
A18: 2. Rumus Regula Falsi: x = a - f(a)*(b-a)/(f(b)-f(a)). Batas diperbarui: jika tanda f(x) sama dengan f(a) maka a = x, selain itu b = x.
A19: 3. Kriteria berhenti: |x(k) - x(k-1)| < 0,001 DAN |f(x(k))| < 0,001.
A20: 4. Soal 4 (x-5)^4: f(x) selalu >= 0 sehingga tidak ada perubahan tanda; Regula Falsi tidak berlaku, akar rangkap x = 5.
A21: 5. Soal 7: 'log' diartikan logaritma basis 10. Soal 9: ditulis ulang sebagai x - e^(-x) (penulisan asli 'x - e - x' tidak bermakna).

Sheet Soal 1
A1: SOAL 1 - METODE REGULA FALSI
A2: f(x) = x^2 - 3x + 1 = 0
A3: Interval: | B3: a = | C3: 0 | D3: b = | E3: 1
A4: Toleransi: | B4: 0.001 | C4: berhenti bila |x(k) - x(k-1)| < tol dan |f(x)| < tol
A6: Iterasi k | B6: a | C6: b | D6: x(k) | E6: f(a) | F6: f(b) | G6: f(x(k)) | H6: |x(k)-x(k-1)| | I6: |f(x(k))| | J6: selesai? | K6: Status
A7: 1 | B7: =C3 | C7: =E3 | D7: =IFERROR(B7-E7*(C7-B7)/(F7-E7),"") | E7: =B7^2-3*B7+1 | F7: =C7^2-3*C7+1 | G7: =D7^2-3*D7+1 | I7: =IF(ISNUMBER(G7),ABS(G7),"") | J7: =IF(AND(ISNUMBER(H7),H7<$B$4,I7<$B$4),TRUE,FALSE) | K7: =IF(J7,"<= KONVERGEN","lanjut")
A8: 2 | B8: =IF(J7,B7,IF(SIGN(G7)=SIGN(E7),D7,B7)) | C8: =IF(J7,C7,IF(SIGN(G7)=SIGN(E7),C7,D7)) | D8: =IF(J7,D7,IFERROR(B8-E8*(C8-B8)/(F8-E8),D7)) | E8: =B8^2-3*B8+1 | F8: =C8^2-3*C8+1 | G8: =D8^2-3*D8+1 | H8: =ABS(D8-D7) | I8: =IF(ISNUMBER(G8),ABS(G8),"") | J8: =IF(OR(J7,AND(ISNUMBER(H8),H8<$B$4,I8<$B$4)),TRUE,FALSE) | K8: =IF(AND(J8,NOT(J7)),"<= KONVERGEN",IF(J8,"","lanjut"))
A9: 3 | B9: =IF(J8,B8,IF(SIGN(G8)=SIGN(E8),D8,B8)) | C9: =IF(J8,C8,IF(SIGN(G8)=SIGN(E8),C8,D8)) | D9: =IF(J8,D8,IFERROR(B9-E9*(C9-B9)/(F9-E9),D8)) | E9: =B9^2-3*B9+1 | F9: =C9^2-3*C9+1 | G9: =D9^2-3*D9+1 | H9: =ABS(D9-D8) | I9: =IF(ISNUMBER(G9),ABS(G9),"") | J9: =IF(OR(J8,AND(ISNUMBER(H9),H9<$B$4,I9<$B$4)),TRUE,FALSE) | K9: =IF(AND(J9,NOT(J8)),"<= KONVERGEN",IF(J9,"","lanjut"))
A10: 4 | B10: =IF(J9,B9,IF(SIGN(G9)=SIGN(E9),D9,B9)) | C10: =IF(J9,C9,IF(SIGN(G9)=SIGN(E9),C9,D9)) | D10: =IF(J9,D9,IFERROR(B10-E10*(C10-B10)/(F10-E10),D9)) | E10: =B10^2-3*B10+1 | F10: =C10^2-3*C10+1 | G10: =D10^2-3*D10+1 | H10: =ABS(D10-D9) | I10: =IF(ISNUMBER(G10),ABS(G10),"") | J10: =IF(OR(J9,AND(ISNUMBER(H10),H10<$B$4,I10<$B$4)),TRUE,FALSE) | K10: =IF(AND(J10,NOT(J9)),"<= KONVERGEN",IF(J10,"","lanjut"))
A11: 5 | B11: =IF(J10,B10,IF(SIGN(G10)=SIGN(E10),D10,B10)) | C11: =IF(J10,C10,IF(SIGN(G10)=SIGN(E10),C10,D10)) | D11: =IF(J10,D10,IFERROR(B11-E11*(C11-B11)/(F11-E11),D10)) | E11: =B11^2-3*B11+1 | F11: =C11^2-3*C11+1 | G11: =D11^2-3*D11+1 | H11: =ABS(D11-D10) | I11: =IF(ISNUMBER(G11),ABS(G11),"") | J11: =IF(OR(J10,AND(ISNUMBER(H11),H11<$B$4,I11<$B$4)),TRUE,FALSE) | K11: =IF(AND(J11,NOT(J10)),"<= KONVERGEN",IF(J11,"","lanjut"))
A12: 6 | B12: =IF(J11,B11,IF(SIGN(G11)=SIGN(E11),D11,B11)) | C12: =IF(J11,C11,IF(SIGN(G11)=SIGN(E11),C11,D11)) | D12: =IF(J11,D11,IFERROR(B12-E12*(C12-B12)/(F12-E12),D11)) | E12: =B12^2-3*B12+1 | F12: =C12^2-3*C12+1 | G12: =D12^2-3*D12+1 | H12: =ABS(D12-D11) | I12: =IF(ISNUMBER(G12),ABS(G12),"") | J12: =IF(OR(J11,AND(ISNUMBER(H12),H12<$B$4,I12<$B$4)),TRUE,FALSE) | K12: =IF(AND(J12,NOT(J11)),"<= KONVERGEN",IF(J12,"","lanjut"))
A13: 7 | B13: =IF(J12,B12,IF(SIGN(G12)=SIGN(E12),D12,B12)) | C13: =IF(J12,C12,IF(SIGN(G12)=SIGN(E12),C12,D12)) | D13: =IF(J12,D12,IFERROR(B13-E13*(C13-B13)/(F13-E13),D12)) | E13: =B13^2-3*B13+1 | F13: =C13^2-3*C13+1 | G13: =D13^2-3*D13+1 | H13: =ABS(D13-D12) | I13: =IF(ISNUMBER(G13),ABS(G13),"") | J13: =IF(OR(J12,AND(ISNUMBER(H13),H13<$B$4,I13<$B$4)),TRUE,FALSE) | K13: =IF(AND(J13,NOT(J12)),"<= KONVERGEN",IF(J13,"","lanjut"))
A14: 8 | B14: =IF(J13,B13,IF(SIGN(G13)=SIGN(E13),D13,B13)) | C14: =IF(J13,C13,IF(SIGN(G13)=SIGN(E13),C13,D13)) | D14: =IF(J13,D13,IFERROR(B14-E14*(C14-B14)/(F14-E14),D13)) | E14: =B14^2-3*B14+1 | F14: =C14^2-3*C14+1 | G14: =D14^2-3*D14+1 | H14: =ABS(D14-D13) | I14: =IF(ISNUMBER(G14),ABS(G14),"") | J14: =IF(OR(J13,AND(ISNUMBER(H14),H14<$B$4,I14<$B$4)),TRUE,FALSE) | K14: =IF(AND(J14,NOT(J13)),"<= KONVERGEN",IF(J14,"","lanjut"))
A15: 9 | B15: =IF(J14,B14,IF(SIGN(G14)=SIGN(E14),D14,B14)) | C15: =IF(J14,C14,IF(SIGN(G14)=SIGN(E14),C14,D14)) | D15: =IF(J14,D14,IFERROR(B15-E15*(C15-B15)/(F15-E15),D14)) | E15: =B15^2-3*B15+1 | F15: =C15^2-3*C15+1 | G15: =D15^2-3*D15+1 | H15: =ABS(D15-D14) | I15: =IF(ISNUMBER(G15),ABS(G15),"") | J15: =IF(OR(J14,AND(ISNUMBER(H15),H15<$B$4,I15<$B$4)),TRUE,FALSE) | K15: =IF(AND(J15,NOT(J14)),"<= KONVERGEN",IF(J15,"","lanjut"))
A16: 10 | B16: =IF(J15,B15,IF(SIGN(G15)=SIGN(E15),D15,B15)) | C16: =IF(J15,C15,IF(SIGN(G15)=SIGN(E15),C15,D15)) | D16: =IF(J15,D15,IFERROR(B16-E16*(C16-B16)/(F16-E16),D15)) | E16: =B16^2-3*B16+1 | F16: =C16^2-3*C16+1 | G16: =D16^2-3*D16+1 | H16: =ABS(D16-D15) | I16: =IF(ISNUMBER(G16),ABS(G16),"") | J16: =IF(OR(J15,AND(ISNUMBER(H16),H16<$B$4,I16<$B$4)),TRUE,FALSE) | K16: =IF(AND(J16,NOT(J15)),"<= KONVERGEN",IF(J16,"","lanjut"))
A17: 11 | B17: =IF(J16,B16,IF(SIGN(G16)=SIGN(E16),D16,B16)) | C17: =IF(J16,C16,IF(SIGN(G16)=SIGN(E16),C16,D16)) | D17: =IF(J16,D16,IFERROR(B17-E17*(C17-B17)/(F17-E17),D16)) | E17: =B17^2-3*B17+1 | F17: =C17^2-3*C17+1 | G17: =D17^2-3*D17+1 | H17: =ABS(D17-D16) | I17: =IF(ISNUMBER(G17),ABS(G17),"") | J17: =IF(OR(J16,AND(ISNUMBER(H17),H17<$B$4,I17<$B$4)),TRUE,FALSE) | K17: =IF(AND(J17,NOT(J16)),"<= KONVERGEN",IF(J17,"","lanjut"))
A18: 12 | B18: =IF(J17,B17,IF(SIGN(G17)=SIGN(E17),D17,B17)) | C18: =IF(J17,C17,IF(SIGN(G17)=SIGN(E17),C17,D17)) | D18: =IF(J17,D17,IFERROR(B18-E18*(C18-B18)/(F18-E18),D17)) | E18: =B18^2-3*B18+1 | F18: =C18^2-3*C18+1 | G18: =D18^2-3*D18+1 | H18: =ABS(D18-D17) | I18: =IF(ISNUMBER(G18),ABS(G18),"") | J18: =IF(OR(J17,AND(ISNUMBER(H18),H18<$B$4,I18<$B$4)),TRUE,FALSE) | K18: =IF(AND(J18,NOT(J17)),"<= KONVERGEN",IF(J18,"","lanjut"))
A19: 13 | B19: =IF(J18,B18,IF(SIGN(G18)=SIGN(E18),D18,B18)) | C19: =IF(J18,C18,IF(SIGN(G18)=SIGN(E18),C18,D18)) | D19: =IF(J18,D18,IFERROR(B19-E19*(C19-B19)/(F19-E19),D18)) | E19: =B19^2-3*B19+1 | F19: =C19^2-3*C19+1 | G19: =D19^2-3*D19+1 | H19: =ABS(D19-D18) | I19: =IF(ISNUMBER(G19),ABS(G19),"") | J19: =IF(OR(J18,AND(ISNUMBER(H19),H19<$B$4,I19<$B$4)),TRUE,FALSE) | K19: =IF(AND(J19,NOT(J18)),"<= KONVERGEN",IF(J19,"","lanjut"))
... A26: 20 | B26: =IF(J25,B25,IF(SIGN(G25)=SIGN(E25),D25,B25)) | C26: =IF(J25,C25,IF(SIGN(G25)=SIGN(E25),C25,D25)) | D26: =IF(J25,D25,IFERROR(B26-E26*(C26-B26)/(F26-E26),D25)) | E26: =B26^2-3*B26+1 | F26: =C26^2-3*C26+1 | G26: =D26^2-3*D26+1 | H26: =ABS(D26-D25) | I26: =IF(ISNUMBER(G26),ABS(G26),"") | J26: =IF(OR(J25,AND(ISNUMBER(H26),H26<$B$4,I26<$B$4)),TRUE,FALSE) | K26: =IF(AND(J26,NOT(J25)),"<= KONVERGEN",IF(J26,"","lanjut"))
A28: Akar: | B28: =D26 | D28: f(akar): | E28: =G26
A29: Jumlah iterasi sampai konvergen: | D29: =IFERROR(MATCH(TRUE,J7:J26,0),"-")

Sheet Soal 2
A1: SOAL 2 - METODE REGULA FALSI
A2: f(x) = tan(pi - x) - x = 0
A3: Interval: | B3: a = | C3: 2 | D3: b = | E3: 2.1
A4: Toleransi: | B4: 0.001 | C4: berhenti bila |x(k) - x(k-1)| < tol dan |f(x)| < tol
A6: Iterasi k | B6: a | C6: b | D6: x(k) | E6: f(a) | F6: f(b) | G6: f(x(k)) | H6: |x(k)-x(k-1)| | I6: |f(x(k))| | J6: selesai? | K6: Status
A7: 1 | B7: =C3 | C7: =E3 | D7: =IFERROR(B7-E7*(C7-B7)/(F7-E7),"") | E7: =TAN(PI()-B7)-B7 | F7: =TAN(PI()-C7)-C7 | G7: =TAN(PI()-D7)-D7 | I7: =IF(ISNUMBER(G7),ABS(G7),"") | J7: =IF(AND(ISNUMBER(H7),H7<$B$4,I7<$B$4),TRUE,FALSE) | K7: =IF(J7,"<= KONVERGEN","lanjut")
A8: 2 | B8: =IF(J7,B7,IF(SIGN(G7)=SIGN(E7),D7,B7)) | C8: =IF(J7,C7,IF(SIGN(G7)=SIGN(E7),C7,D7)) | D8: =IF(J7,D7,IFERROR(B8-E8*(C8-B8)/(F8-E8),D7)) | E8: =TAN(PI()-B8)-B8 | F8: =TAN(PI()-C8)-C8 | G8: =TAN(PI()-D8)-D8 | H8: =ABS(D8-D7) | I8: =IF(ISNUMBER(G8),ABS(G8),"") | J8: =IF(OR(J7,AND(ISNUMBER(H8),H8<$B$4,I8<$B$4)),TRUE,FALSE) | K8: =IF(AND(J8,NOT(J7)),"<= KONVERGEN",IF(J8,"","lanjut"))
A9: 3 | B9: =IF(J8,B8,IF(SIGN(G8)=SIGN(E8),D8,B8)) | C9: =IF(J8,C8,IF(SIGN(G8)=SIGN(E8),C8,D8)) | D9: =IF(J8,D8,IFERROR(B9-E9*(C9-B9)/(F9-E9),D8)) | E9: =TAN(PI()-B9)-B9 | F9: =TAN(PI()-C9)-C9 | G9: =TAN(PI()-D9)-D9 | H9: =ABS(D9-D8) | I9: =IF(ISNUMBER(G9),ABS(G9),"") | J9: =IF(OR(J8,AND(ISNUMBER(H9),H9<$B$4,I9<$B$4)),TRUE,FALSE) | K9: =IF(AND(J9,NOT(J8)),"<= KONVERGEN",IF(J9,"","lanjut"))
A10: 4 | B10: =IF(J9,B9,IF(SIGN(G9)=SIGN(E9),D9,B9)) | C10: =IF(J9,C9,IF(SIGN(G9)=SIGN(E9),C9,D9)) | D10: =IF(J9,D9,IFERROR(B10-E10*(C10-B10)/(F10-E10),D9)) | E10: =TAN(PI()-B10)-B10 | F10: =TAN(PI()-C10)-C10 | G10: =TAN(PI()-D10)-D10 | H10: =ABS(D10-D9) | I10: =IF(ISNUMBER(G10),ABS(G10),"") | J10: =IF(OR(J9,AND(ISNUMBER(H10),H10<$B$4,I10<$B$4)),TRUE,FALSE) | K10: =IF(AND(J10,NOT(J9)),"<= KONVERGEN",IF(J10,"","lanjut"))
A11: 5 | B11: =IF(J10,B10,IF(SIGN(G10)=SIGN(E10),D10,B10)) | C11: =IF(J10,C10,IF(SIGN(G10)=SIGN(E10),C10,D10)) | D11: =IF(J10,D10,IFERROR(B11-E11*(C11-B11)/(F11-E11),D10)) | E11: =TAN(PI()-B11)-B11 | F11: =TAN(PI()-C11)-C11 | G11: =TAN(PI()-D11)-D11 | H11: =ABS(D11-D10) | I11: =IF(ISNUMBER(G11),ABS(G11),"") | J11: =IF(OR(J10,AND(ISNUMBER(H11),H11<$B$4,I11<$B$4)),TRUE,FALSE) | K11: =IF(AND(J11,NOT(J10)),"<= KONVERGEN",IF(J11,"","lanjut"))
A12: 6 | B12: =IF(J11,B11,IF(SIGN(G11)=SIGN(E11),D11,B11)) | C12: =IF(J11,C11,IF(SIGN(G11)=SIGN(E11),C11,D11)) | D12: =IF(J11,D11,IFERROR(B12-E12*(C12-B12)/(F12-E12),D11)) | E12: =TAN(PI()-B12)-B12 | F12: =TAN(PI()-C12)-C12 | G12: =TAN(PI()-D12)-D12 | H12: =ABS(D12-D11) | I12: =IF(ISNUMBER(G12),ABS(G12),"") | J12: =IF(OR(J11,AND(ISNUMBER(H12),H12<$B$4,I12<$B$4)),TRUE,FALSE) | K12: =IF(AND(J12,NOT(J11)),"<= KONVERGEN",IF(J12,"","lanjut"))
A13: 7 | B13: =IF(J12,B12,IF(SIGN(G12)=SIGN(E12),D12,B12)) | C13: =IF(J12,C12,IF(SIGN(G12)=SIGN(E12),C12,D12)) | D13: =IF(J12,D12,IFERROR(B13-E13*(C13-B13)/(F13-E13),D12)) | E13: =TAN(PI()-B13)-B13 | F13: =TAN(PI()-C13)-C13 | G13: =TAN(PI()-D13)-D13 | H13: =ABS(D13-D12) | I13: =IF(ISNUMBER(G13),ABS(G13),"") | J13: =IF(OR(J12,AND(ISNUMBER(H13),H13<$B$4,I13<$B$4)),TRUE,FALSE) | K13: =IF(AND(J13,NOT(J12)),"<= KONVERGEN",IF(J13,"","lanjut"))
A14: 8 | B14: =IF(J13,B13,IF(SIGN(G13)=SIGN(E13),D13,B13)) | C14: =IF(J13,C13,IF(SIGN(G13)=SIGN(E13),C13,D13)) | D14: =IF(J13,D13,IFERROR(B14-E14*(C14-B14)/(F14-E14),D13)) | E14: =TAN(PI()-B14)-B14 | F14: =TAN(PI()-C14)-C14 | G14: =TAN(PI()-D14)-D14 | H14: =ABS(D14-D13) | I14: =IF(ISNUMBER(G14),ABS(G14),"") | J14: =IF(OR(J13,AND(ISNUMBER(H14),H14<$B$4,I14<$B$4)),TRUE,FALSE) | K14: =IF(AND(J14,NOT(J13)),"<= KONVERGEN",IF(J14,"","lanjut"))
A15: 9 | B15: =IF(J14,B14,IF(SIGN(G14)=SIGN(E14),D14,B14)) | C15: =IF(J14,C14,IF(SIGN(G14)=SIGN(E14),C14,D14)) | D15: =IF(J14,D14,IFERROR(B15-E15*(C15-B15)/(F15-E15),D14)) | E15: =TAN(PI()-B15)-B15 | F15: =TAN(PI()-C15)-C15 | G15: =TAN(PI()-D15)-D15 | H15: =ABS(D15-D14) | I15: =IF(ISNUMBER(G15),ABS(G15),"") | J15: =IF(OR(J14,AND(ISNUMBER(H15),H15<$B$4,I15<$B$4)),TRUE,FALSE) | K15: =IF(AND(J15,NOT(J14)),"<= KONVERGEN",IF(J15,"","lanjut"))
A16: 10 | B16: =IF(J15,B15,IF(SIGN(G15)=SIGN(E15),D15,B15)) | C16: =IF(J15,C15,IF(SIGN(G15)=SIGN(E15),C15,D15)) | D16: =IF(J15,D15,IFERROR(B16-E16*(C16-B16)/(F16-E16),D15)) | E16: =TAN(PI()-B16)-B16 | F16: =TAN(PI()-C16)-C16 | G16: =TAN(PI()-D16)-D16 | H16: =ABS(D16-D15) | I16: =IF(ISNUMBER(G16),ABS(G16),"") | J16: =IF(OR(J15,AND(ISNUMBER(H16),H16<$B$4,I16<$B$4)),TRUE,FALSE) | K16: =IF(AND(J16,NOT(J15)),"<= KONVERGEN",IF(J16,"","lanjut"))
A17: 11 | B17: =IF(J16,B16,IF(SIGN(G16)=SIGN(E16),D16,B16)) | C17: =IF(J16,C16,IF(SIGN(G16)=SIGN(E16),C16,D16)) | D17: =IF(J16,D16,IFERROR(B17-E17*(C17-B17)/(F17-E17),D16)) | E17: =TAN(PI()-B17)-B17 | F17: =TAN(PI()-C17)-C17 | G17: =TAN(PI()-D17)-D17 | H17: =ABS(D17-D16) | I17: =IF(ISNUMBER(G17),ABS(G17),"") | J17: =IF(OR(J16,AND(ISNUMBER(H17),H17<$B$4,I17<$B$4)),TRUE,FALSE) | K17: =IF(AND(J17,NOT(J16)),"<= KONVERGEN",IF(J17,"","lanjut"))
A18: 12 | B18: =IF(J17,B17,IF(SIGN(G17)=SIGN(E17),D17,B17)) | C18: =IF(J17,C17,IF(SIGN(G17)=SIGN(E17),C17,D17)) | D18: =IF(J17,D17,IFERROR(B18-E18*(C18-B18)/(F18-E18),D17)) | E18: =TAN(PI()-B18)-B18 | F18: =TAN(PI()-C18)-C18 | G18: =TAN(PI()-D18)-D18 | H18: =ABS(D18-D17) | I18: =IF(ISNUMBER(G18),ABS(G18),"") | J18: =IF(OR(J17,AND(ISNUMBER(H18),H18<$B$4,I18<$B$4)),TRUE,FALSE) | K18: =IF(AND(J18,NOT(J17)),"<= KONVERGEN",IF(J18,"","lanjut"))
A19: 13 | B19: =IF(J18,B18,IF(SIGN(G18)=SIGN(E18),D18,B18)) | C19: =IF(J18,C18,IF(SIGN(G18)=SIGN(E18),C18,D18)) | D19: =IF(J18,D18,IFERROR(B19-E19*(C19-B19)/(F19-E19),D18)) | E19: =TAN(PI()-B19)-B19 | F19: =TAN(PI()-C19)-C19 | G19: =TAN(PI()-D19)-D19 | H19: =ABS(D19-D18) | I19: =IF(ISNUMBER(G19),ABS(G19),"") | J19: =IF(OR(J18,AND(ISNUMBER(H19),H19<$B$4,I19<$B$4)),TRUE,FALSE) | K19: =IF(AND(J19,NOT(J18)),"<= KONVERGEN",IF(J19,"","lanjut"))
... A26: 20 | B26: =IF(J25,B25,IF(SIGN(G25)=SIGN(E25),D25,B25)) | C26: =IF(J25,C25,IF(SIGN(G25)=SIGN(E25),C25,D25)) | D26: =IF(J25,D25,IFERROR(B26-E26*(C26-B26)/(F26-E26),D25)) | E26: =TAN(PI()-B26)-B26 | F26: =TAN(PI()-C26)-C26 | G26: =TAN(PI()-D26)-D26 | H26: =ABS(D26-D25) | I26: =IF(ISNUMBER(G26),ABS(G26),"") | J26: =IF(OR(J25,AND(ISNUMBER(H26),H26<$B$4,I26<$B$4)),TRUE,FALSE) | K26: =IF(AND(J26,NOT(J25)),"<= KONVERGEN",IF(J26,"","lanjut"))
A28: Akar: | B28: =D26 | D28: f(akar): | E28: =G26
A29: Jumlah iterasi sampai konvergen: | D29: =IFERROR(MATCH(TRUE,J7:J26,0),"-")

Sheet Soal 3
A1: SOAL 3 - METODE REGULA FALSI
A2: f(x) = x^3 - x^2 - x + 1 = 0
A3: Interval: | B3: a = | C3: -1.5 | D3: b = | E3: -0.5
A4: Toleransi: | B4: 0.001 | C4: berhenti bila |x(k) - x(k-1)| < tol dan |f(x)| < tol
A6: Iterasi k | B6: a | C6: b | D6: x(k) | E6: f(a) | F6: f(b) | G6: f(x(k)) | H6: |x(k)-x(k-1)| | I6: |f(x(k))| | J6: selesai? | K6: Status
A7: 1 | B7: =C3 | C7: =E3 | D7: =IFERROR(B7-E7*(C7-B7)/(F7-E7),"") | E7: =B7^3-B7^2-B7+1 | F7: =C7^3-C7^2-C7+1 | G7: =D7^3-D7^2-D7+1 | I7: =IF(ISNUMBER(G7),ABS(G7),"") | J7: =IF(AND(ISNUMBER(H7),H7<$B$4,I7<$B$4),TRUE,FALSE) | K7: =IF(J7,"<= KONVERGEN","lanjut")
A8: 2 | B8: =IF(J7,B7,IF(SIGN(G7)=SIGN(E7),D7,B7)) | C8: =IF(J7,C7,IF(SIGN(G7)=SIGN(E7),C7,D7)) | D8: =IF(J7,D7,IFERROR(B8-E8*(C8-B8)/(F8-E8),D7)) | E8: =B8^3-B8^2-B8+1 | F8: =C8^3-C8^2-C8+1 | G8: =D8^3-D8^2-D8+1 | H8: =ABS(D8-D7) | I8: =IF(ISNUMBER(G8),ABS(G8),"") | J8: =IF(OR(J7,AND(ISNUMBER(H8),H8<$B$4,I8<$B$4)),TRUE,FALSE) | K8: =IF(AND(J8,NOT(J7)),"<= KONVERGEN",IF(J8,"","lanjut"))
A9: 3 | B9: =IF(J8,B8,IF(SIGN(G8)=SIGN(E8),D8,B8)) | C9: =IF(J8,C8,IF(SIGN(G8)=SIGN(E8),C8,D8)) | D9: =IF(J8,D8,IFERROR(B9-E9*(C9-B9)/(F9-E9),D8)) | E9: =B9^3-B9^2-B9+1 | F9: =C9^3-C9^2-C9+1 | G9: =D9^3-D9^2-D9+1 | H9: =ABS(D9-D8) | I9: =IF(ISNUMBER(G9),ABS(G9),"") | J9: =IF(OR(J8,AND(ISNUMBER(H9),H9<$B$4,I9<$B$4)),TRUE,FALSE) | K9: =IF(AND(J9,NOT(J8)),"<= KONVERGEN",IF(J9,"","lanjut"))
A10: 4 | B10: =IF(J9,B9,IF(SIGN(G9)=SIGN(E9),D9,B9)) | C10: =IF(J9,C9,IF(SIGN(G9)=SIGN(E9),C9,D9)) | D10: =IF(J9,D9,IFERROR(B10-E10*(C10-B10)/(F10-E10),D9)) | E10: =B10^3-B10^2-B10+1 | F10: =C10^3-C10^2-C10+1 | G10: =D10^3-D10^2-D10+1 | H10: =ABS(D10-D9) | I10: =IF(ISNUMBER(G10),ABS(G10),"") | J10: =IF(OR(J9,AND(ISNUMBER(H10),H10<$B$4,I10<$B$4)),TRUE,FALSE) | K10: =IF(AND(J10,NOT(J9)),"<= KONVERGEN",IF(J10,"","lanjut"))
A11: 5 | B11: =IF(J10,B10,IF(SIGN(G10)=SIGN(E10),D10,B10)) | C11: =IF(J10,C10,IF(SIGN(G10)=SIGN(E10),C10,D10)) | D11: =IF(J10,D10,IFERROR(B11-E11*(C11-B11)/(F11-E11),D10)) | E11: =B11^3-B11^2-B11+1 | F11: =C11^3-C11^2-C11+1 | G11: =D11^3-D11^2-D11+1 | H11: =ABS(D11-D10) | I11: =IF(ISNUMBER(G11),ABS(G11),"") | J11: =IF(OR(J10,AND(ISNUMBER(H11),H11<$B$4,I11<$B$4)),TRUE,FALSE) | K11: =IF(AND(J11,NOT(J10)),"<= KONVERGEN",IF(J11,"","lanjut"))
A12: 6 | B12: =IF(J11,B11,IF(SIGN(G11)=SIGN(E11),D11,B11)) | C12: =IF(J11,C11,IF(SIGN(G11)=SIGN(E11),C11,D11)) | D12: =IF(J11,D11,IFERROR(B12-E12*(C12-B12)/(F12-E12),D11)) | E12: =B12^3-B12^2-B12+1 | F12: =C12^3-C12^2-C12+1 | G12: =D12^3-D12^2-D12+1 | H12: =ABS(D12-D11) | I12: =IF(ISNUMBER(G12),ABS(G12),"") | J12: =IF(OR(J11,AND(ISNUMBER(H12),H12<$B$4,I12<$B$4)),TRUE,FALSE) | K12: =IF(AND(J12,NOT(J11)),"<= KONVERGEN",IF(J12,"","lanjut"))
A13: 7 | B13: =IF(J12,B12,IF(SIGN(G12)=SIGN(E12),D12,B12)) | C13: =IF(J12,C12,IF(SIGN(G12)=SIGN(E12),C12,D12)) | D13: =IF(J12,D12,IFERROR(B13-E13*(C13-B13)/(F13-E13),D12)) | E13: =B13^3-B13^2-B13+1 | F13: =C13^3-C13^2-C13+1 | G13: =D13^3-D13^2-D13+1 | H13: =ABS(D13-D12) | I13: =IF(ISNUMBER(G13),ABS(G13),"") | J13: =IF(OR(J12,AND(ISNUMBER(H13),H13<$B$4,I13<$B$4)),TRUE,FALSE) | K13: =IF(AND(J13,NOT(J12)),"<= KONVERGEN",IF(J13,"","lanjut"))
A14: 8 | B14: =IF(J13,B13,IF(SIGN(G13)=SIGN(E13),D13,B13)) | C14: =IF(J13,C13,IF(SIGN(G13)=SIGN(E13),C13,D13)) | D14: =IF(J13,D13,IFERROR(B14-E14*(C14-B14)/(F14-E14),D13)) | E14: =B14^3-B14^2-B14+1 | F14: =C14^3-C14^2-C14+1 | G14: =D14^3-D14^2-D14+1 | H14: =ABS(D14-D13) | I14: =IF(ISNUMBER(G14),ABS(G14),"") | J14: =IF(OR(J13,AND(ISNUMBER(H14),H14<$B$4,I14<$B$4)),TRUE,FALSE) | K14: =IF(AND(J14,NOT(J13)),"<= KONVERGEN",IF(J14,"","lanjut"))
A15: 9 | B15: =IF(J14,B14,IF(SIGN(G14)=SIGN(E14),D14,B14)) | C15: =IF(J14,C14,IF(SIGN(G14)=SIGN(E14),C14,D14)) | D15: =IF(J14,D14,IFERROR(B15-E15*(C15-B15)/(F15-E15),D14)) | E15: =B15^3-B15^2-B15+1 | F15: =C15^3-C15^2-C15+1 | G15: =D15^3-D15^2-D15+1 | H15: =ABS(D15-D14) | I15: =IF(ISNUMBER(G15),ABS(G15),"") | J15: =IF(OR(J14,AND(ISNUMBER(H15),H15<$B$4,I15<$B$4)),TRUE,FALSE) | K15: =IF(AND(J15,NOT(J14)),"<= KONVERGEN",IF(J15,"","lanjut"))
A16: 10 | B16: =IF(J15,B15,IF(SIGN(G15)=SIGN(E15),D15,B15)) | C16: =IF(J15,C15,IF(SIGN(G15)=SIGN(E15),C15,D15)) | D16: =IF(J15,D15,IFERROR(B16-E16*(C16-B16)/(F16-E16),D15)) | E16: =B16^3-B16^2-B16+1 | F16: =C16^3-C16^2-C16+1 | G16: =D16^3-D16^2-D16+1 | H16: =ABS(D16-D15) | I16: =IF(ISNUMBER(G16),ABS(G16),"") | J16: =IF(OR(J15,AND(ISNUMBER(H16),H16<$B$4,I16<$B$4)),TRUE,FALSE) | K16: =IF(AND(J16,NOT(J15)),"<= KONVERGEN",IF(J16,"","lanjut"))
A17: 11 | B17: =IF(J16,B16,IF(SIGN(G16)=SIGN(E16),D16,B16)) | C17: =IF(J16,C16,IF(SIGN(G16)=SIGN(E16),C16,D16)) | D17: =IF(J16,D16,IFERROR(B17-E17*(C17-B17)/(F17-E17),D16)) | E17: =B17^3-B17^2-B17+1 | F17: =C17^3-C17^2-C17+1 | G17: =D17^3-D17^2-D17+1 | H17: =ABS(D17-D16) | I17: =IF(ISNUMBER(G17),ABS(G17),"") | J17: =IF(OR(J16,AND(ISNUMBER(H17),H17<$B$4,I17<$B$4)),TRUE,FALSE) | K17: =IF(AND(J17,NOT(J16)),"<= KONVERGEN",IF(J17,"","lanjut"))
A18: 12 | B18: =IF(J17,B17,IF(SIGN(G17)=SIGN(E17),D17,B17)) | C18: =IF(J17,C17,IF(SIGN(G17)=SIGN(E17),C17,D17)) | D18: =IF(J17,D17,IFERROR(B18-E18*(C18-B18)/(F18-E18),D17)) | E18: =B18^3-B18^2-B18+1 | F18: =C18^3-C18^2-C18+1 | G18: =D18^3-D18^2-D18+1 | H18: =ABS(D18-D17) | I18: =IF(ISNUMBER(G18),ABS(G18),"") | J18: =IF(OR(J17,AND(ISNUMBER(H18),H18<$B$4,I18<$B$4)),TRUE,FALSE) | K18: =IF(AND(J18,NOT(J17)),"<= KONVERGEN",IF(J18,"","lanjut"))
A19: 13 | B19: =IF(J18,B18,IF(SIGN(G18)=SIGN(E18),D18,B18)) | C19: =IF(J18,C18,IF(SIGN(G18)=SIGN(E18),C18,D18)) | D19: =IF(J18,D18,IFERROR(B19-E19*(C19-B19)/(F19-E19),D18)) | E19: =B19^3-B19^2-B19+1 | F19: =C19^3-C19^2-C19+1 | G19: =D19^3-D19^2-D19+1 | H19: =ABS(D19-D18) | I19: =IF(ISNUMBER(G19),ABS(G19),"") | J19: =IF(OR(J18,AND(ISNUMBER(H19),H19<$B$4,I19<$B$4)),TRUE,FALSE) | K19: =IF(AND(J19,NOT(J18)),"<= KONVERGEN",IF(J19,"","lanjut"))
... A26: 20 | B26: =IF(J25,B25,IF(SIGN(G25)=SIGN(E25),D25,B25)) | C26: =IF(J25,C25,IF(SIGN(G25)=SIGN(E25),C25,D25)) | D26: =IF(J25,D25,IFERROR(B26-E26*(C26-B26)/(F26-E26),D25)) | E26: =B26^3-B26^2-B26+1 | F26: =C26^3-C26^2-C26+1 | G26: =D26^3-D26^2-D26+1 | H26: =ABS(D26-D25) | I26: =IF(ISNUMBER(G26),ABS(G26),"") | J26: =IF(OR(J25,AND(ISNUMBER(H26),H26<$B$4,I26<$B$4)),TRUE,FALSE) | K26: =IF(AND(J26,NOT(J25)),"<= KONVERGEN",IF(J26,"","lanjut"))
A28: Akar: | B28: =D26 | D28: f(akar): | E28: =G26
A29: Jumlah iterasi sampai konvergen: | D29: =IFERROR(MATCH(TRUE,J7:J26,0),"-")

Sheet Soal 4
A1: SOAL 4 - METODE REGULA FALSI
A2: f(x) = (x - 5)^4 = 0
A3: Interval: | B3: a = | C3: 4 | D3: b = | E3: 6
A4: Toleransi: | B4: 0.001 | C4: berhenti bila |x(k) - x(k-1)| < tol dan |f(x)| < tol
A6: Cek perubahan tanda pada interval awal:
A7: f(a) = | B7: =(C3-5)^4
A8: f(b) = | B8: =(E3-5)^4
A9: f(a) x f(b) = | B9: =B7*B8
A11: Karena f(a) x f(b) > 0 (tidak ada perubahan tanda), metode Regula Falsi
A12: tidak dapat diterapkan. f(x) = (x-5)^4 selalu >= 0, jadi kurva hanya
A13: menyentuh sumbu-x tanpa memotongnya.
A15: Akar (analitis): x = 5 (akar rangkap/multiplisitas 4)

Sheet Soal 5
A1: SOAL 5 - METODE REGULA FALSI
A2: f(x) = x^3 - 4x + 1 = 0
A3: Interval: | B3: a = | C3: 0 | D3: b = | E3: 1
A4: Toleransi: | B4: 0.001 | C4: berhenti bila |x(k) - x(k-1)| < tol dan |f(x)| < tol
A6: Iterasi k | B6: a | C6: b | D6: x(k) | E6: f(a) | F6: f(b) | G6: f(x(k)) | H6: |x(k)-x(k-1)| | I6: |f(x(k))| | J6: selesai? | K6: Status
A7: 1 | B7: =C3 | C7: =E3 | D7: =IFERROR(B7-E7*(C7-B7)/(F7-E7),"") | E7: =B7^3-4*B7+1 | F7: =C7^3-4*C7+1 | G7: =D7^3-4*D7+1 | I7: =IF(ISNUMBER(G7),ABS(G7),"") | J7: =IF(AND(ISNUMBER(H7),H7<$B$4,I7<$B$4),TRUE,FALSE) | K7: =IF(J7,"<= KONVERGEN","lanjut")
A8: 2 | B8: =IF(J7,B7,IF(SIGN(G7)=SIGN(E7),D7,B7)) | C8: =IF(J7,C7,IF(SIGN(G7)=SIGN(E7),C7,D7)) | D8: =IF(J7,D7,IFERROR(B8-E8*(C8-B8)/(F8-E8),D7)) | E8: =B8^3-4*B8+1 | F8: =C8^3-4*C8+1 | G8: =D8^3-4*D8+1 | H8: =ABS(D8-D7) | I8: =IF(ISNUMBER(G8),ABS(G8),"") | J8: =IF(OR(J7,AND(ISNUMBER(H8),H8<$B$4,I8<$B$4)),TRUE,FALSE) | K8: =IF(AND(J8,NOT(J7)),"<= KONVERGEN",IF(J8,"","lanjut"))
A9: 3 | B9: =IF(J8,B8,IF(SIGN(G8)=SIGN(E8),D8,B8)) | C9: =IF(J8,C8,IF(SIGN(G8)=SIGN(E8),C8,D8)) | D9: =IF(J8,D8,IFERROR(B9-E9*(C9-B9)/(F9-E9),D8)) | E9: =B9^3-4*B9+1 | F9: =C9^3-4*C9+1 | G9: =D9^3-4*D9+1 | H9: =ABS(D9-D8) | I9: =IF(ISNUMBER(G9),ABS(G9),"") | J9: =IF(OR(J8,AND(ISNUMBER(H9),H9<$B$4,I9<$B$4)),TRUE,FALSE) | K9: =IF(AND(J9,NOT(J8)),"<= KONVERGEN",IF(J9,"","lanjut"))
A10: 4 | B10: =IF(J9,B9,IF(SIGN(G9)=SIGN(E9),D9,B9)) | C10: =IF(J9,C9,IF(SIGN(G9)=SIGN(E9),C9,D9)) | D10: =IF(J9,D9,IFERROR(B10-E10*(C10-B10)/(F10-E10),D9)) | E10: =B10^3-4*B10+1 | F10: =C10^3-4*C10+1 | G10: =D10^3-4*D10+1 | H10: =ABS(D10-D9) | I10: =IF(ISNUMBER(G10),ABS(G10),"") | J10: =IF(OR(J9,AND(ISNUMBER(H10),H10<$B$4,I10<$B$4)),TRUE,FALSE) | K10: =IF(AND(J10,NOT(J9)),"<= KONVERGEN",IF(J10,"","lanjut"))
A11: 5 | B11: =IF(J10,B10,IF(SIGN(G10)=SIGN(E10),D10,B10)) | C11: =IF(J10,C10,IF(SIGN(G10)=SIGN(E10),C10,D10)) | D11: =IF(J10,D10,IFERROR(B11-E11*(C11-B11)/(F11-E11),D10)) | E11: =B11^3-4*B11+1 | F11: =C11^3-4*C11+1 | G11: =D11^3-4*D11+1 | H11: =ABS(D11-D10) | I11: =IF(ISNUMBER(G11),ABS(G11),"") | J11: =IF(OR(J10,AND(ISNUMBER(H11),H11<$B$4,I11<$B$4)),TRUE,FALSE) | K11: =IF(AND(J11,NOT(J10)),"<= KONVERGEN",IF(J11,"","lanjut"))
A12: 6 | B12: =IF(J11,B11,IF(SIGN(G11)=SIGN(E11),D11,B11)) | C12: =IF(J11,C11,IF(SIGN(G11)=SIGN(E11),C11,D11)) | D12: =IF(J11,D11,IFERROR(B12-E12*(C12-B12)/(F12-E12),D11)) | E12: =B12^3-4*B12+1 | F12: =C12^3-4*C12+1 | G12: =D12^3-4*D12+1 | H12: =ABS(D12-D11) | I12: =IF(ISNUMBER(G12),ABS(G12),"") | J12: =IF(OR(J11,AND(ISNUMBER(H12),H12<$B$4,I12<$B$4)),TRUE,FALSE) | K12: =IF(AND(J12,NOT(J11)),"<= KONVERGEN",IF(J12,"","lanjut"))
A13: 7 | B13: =IF(J12,B12,IF(SIGN(G12)=SIGN(E12),D12,B12)) | C13: =IF(J12,C12,IF(SIGN(G12)=SIGN(E12),C12,D12)) | D13: =IF(J12,D12,IFERROR(B13-E13*(C13-B13)/(F13-E13),D12)) | E13: =B13^3-4*B13+1 | F13: =C13^3-4*C13+1 | G13: =D13^3-4*D13+1 | H13: =ABS(D13-D12) | I13: =IF(ISNUMBER(G13),ABS(G13),"") | J13: =IF(OR(J12,AND(ISNUMBER(H13),H13<$B$4,I13<$B$4)),TRUE,FALSE) | K13: =IF(AND(J13,NOT(J12)),"<= KONVERGEN",IF(J13,"","lanjut"))
A14: 8 | B14: =IF(J13,B13,IF(SIGN(G13)=SIGN(E13),D13,B13)) | C14: =IF(J13,C13,IF(SIGN(G13)=SIGN(E13),C13,D13)) | D14: =IF(J13,D13,IFERROR(B14-E14*(C14-B14)/(F14-E14),D13)) | E14: =B14^3-4*B14+1 | F14: =C14^3-4*C14+1 | G14: =D14^3-4*D14+1 | H14: =ABS(D14-D13) | I14: =IF(ISNUMBER(G14),ABS(G14),"") | J14: =IF(OR(J13,AND(ISNUMBER(H14),H14<$B$4,I14<$B$4)),TRUE,FALSE) | K14: =IF(AND(J14,NOT(J13)),"<= KONVERGEN",IF(J14,"","lanjut"))
A15: 9 | B15: =IF(J14,B14,IF(SIGN(G14)=SIGN(E14),D14,B14)) | C15: =IF(J14,C14,IF(SIGN(G14)=SIGN(E14),C14,D14)) | D15: =IF(J14,D14,IFERROR(B15-E15*(C15-B15)/(F15-E15),D14)) | E15: =B15^3-4*B15+1 | F15: =C15^3-4*C15+1 | G15: =D15^3-4*D15+1 | H15: =ABS(D15-D14) | I15: =IF(ISNUMBER(G15),ABS(G15),"") | J15: =IF(OR(J14,AND(ISNUMBER(H15),H15<$B$4,I15<$B$4)),TRUE,FALSE) | K15: =IF(AND(J15,NOT(J14)),"<= KONVERGEN",IF(J15,"","lanjut"))
A16: 10 | B16: =IF(J15,B15,IF(SIGN(G15)=SIGN(E15),D15,B15)) | C16: =IF(J15,C15,IF(SIGN(G15)=SIGN(E15),C15,D15)) | D16: =IF(J15,D15,IFERROR(B16-E16*(C16-B16)/(F16-E16),D15)) | E16: =B16^3-4*B16+1 | F16: =C16^3-4*C16+1 | G16: =D16^3-4*D16+1 | H16: =ABS(D16-D15) | I16: =IF(ISNUMBER(G16),ABS(G16),"") | J16: =IF(OR(J15,AND(ISNUMBER(H16),H16<$B$4,I16<$B$4)),TRUE,FALSE) | K16: =IF(AND(J16,NOT(J15)),"<= KONVERGEN",IF(J16,"","lanjut"))
A17: 11 | B17: =IF(J16,B16,IF(SIGN(G16)=SIGN(E16),D16,B16)) | C17: =IF(J16,C16,IF(SIGN(G16)=SIGN(E16),C16,D16)) | D17: =IF(J16,D16,IFERROR(B17-E17*(C17-B17)/(F17-E17),D16)) | E17: =B17^3-4*B17+1 | F17: =C17^3-4*C17+1 | G17: =D17^3-4*D17+1 | H17: =ABS(D17-D16) | I17: =IF(ISNUMBER(G17),ABS(G17),"") | J17: =IF(OR(J16,AND(ISNUMBER(H17),H17<$B$4,I17<$B$4)),TRUE,FALSE) | K17: =IF(AND(J17,NOT(J16)),"<= KONVERGEN",IF(J17,"","lanjut"))
A18: 12 | B18: =IF(J17,B17,IF(SIGN(G17)=SIGN(E17),D17,B17)) | C18: =IF(J17,C17,IF(SIGN(G17)=SIGN(E17),C17,D17)) | D18: =IF(J17,D17,IFERROR(B18-E18*(C18-B18)/(F18-E18),D17)) | E18: =B18^3-4*B18+1 | F18: =C18^3-4*C18+1 | G18: =D18^3-4*D18+1 | H18: =ABS(D18-D17) | I18: =IF(ISNUMBER(G18),ABS(G18),"") | J18: =IF(OR(J17,AND(ISNUMBER(H18),H18<$B$4,I18<$B$4)),TRUE,FALSE) | K18: =IF(AND(J18,NOT(J17)),"<= KONVERGEN",IF(J18,"","lanjut"))
A19: 13 | B19: =IF(J18,B18,IF(SIGN(G18)=SIGN(E18),D18,B18)) | C19: =IF(J18,C18,IF(SIGN(G18)=SIGN(E18),C18,D18)) | D19: =IF(J18,D18,IFERROR(B19-E19*(C19-B19)/(F19-E19),D18)) | E19: =B19^3-4*B19+1 | F19: =C19^3-4*C19+1 | G19: =D19^3-4*D19+1 | H19: =ABS(D19-D18) | I19: =IF(ISNUMBER(G19),ABS(G19),"") | J19: =IF(OR(J18,AND(ISNUMBER(H19),H19<$B$4,I19<$B$4)),TRUE,FALSE) | K19: =IF(AND(J19,NOT(J18)),"<= KONVERGEN",IF(J19,"","lanjut"))
... A26: 20 | B26: =IF(J25,B25,IF(SIGN(G25)=SIGN(E25),D25,B25)) | C26: =IF(J25,C25,IF(SIGN(G25)=SIGN(E25),C25,D25)) | D26: =IF(J25,D25,IFERROR(B26-E26*(C26-B26)/(F26-E26),D25)) | E26: =B26^3-4*B26+1 | F26: =C26^3-4*C26+1 | G26: =D26^3-4*D26+1 | H26: =ABS(D26-D25) | I26: =IF(ISNUMBER(G26),ABS(G26),"") | J26: =IF(OR(J25,AND(ISNUMBER(H26),H26<$B$4,I26<$B$4)),TRUE,FALSE) | K26: =IF(AND(J26,NOT(J25)),"<= KONVERGEN",IF(J26,"","lanjut"))
A28: Akar: | B28: =D26 | D28: f(akar): | E28: =G26
A29: Jumlah iterasi sampai konvergen: | D29: =IFERROR(MATCH(TRUE,J7:J26,0),"-")

Sheet Soal 6
A1: SOAL 6 - METODE REGULA FALSI
A2: f(x) = x + cos x = 0
A3: Interval: | B3: a = | C3: -1 | D3: b = | E3: 0
A4: Toleransi: | B4: 0.001 | C4: berhenti bila |x(k) - x(k-1)| < tol dan |f(x)| < tol
A6: Iterasi k | B6: a | C6: b | D6: x(k) | E6: f(a) | F6: f(b) | G6: f(x(k)) | H6: |x(k)-x(k-1)| | I6: |f(x(k))| | J6: selesai? | K6: Status
A7: 1 | B7: =C3 | C7: =E3 | D7: =IFERROR(B7-E7*(C7-B7)/(F7-E7),"") | E7: =B7+COS(B7) | F7: =C7+COS(C7) | G7: =D7+COS(D7) | I7: =IF(ISNUMBER(G7),ABS(G7),"") | J7: =IF(AND(ISNUMBER(H7),H7<$B$4,I7<$B$4),TRUE,FALSE) | K7: =IF(J7,"<= KONVERGEN","lanjut")
A8: 2 | B8: =IF(J7,B7,IF(SIGN(G7)=SIGN(E7),D7,B7)) | C8: =IF(J7,C7,IF(SIGN(G7)=SIGN(E7),C7,D7)) | D8: =IF(J7,D7,IFERROR(B8-E8*(C8-B8)/(F8-E8),D7)) | E8: =B8+COS(B8) | F8: =C8+COS(C8) | G8: =D8+COS(D8) | H8: =ABS(D8-D7) | I8: =IF(ISNUMBER(G8),ABS(G8),"") | J8: =IF(OR(J7,AND(ISNUMBER(H8),H8<$B$4,I8<$B$4)),TRUE,FALSE) | K8: =IF(AND(J8,NOT(J7)),"<= KONVERGEN",IF(J8,"","lanjut"))
A9: 3 | B9: =IF(J8,B8,IF(SIGN(G8)=SIGN(E8),D8,B8)) | C9: =IF(J8,C8,IF(SIGN(G8)=SIGN(E8),C8,D8)) | D9: =IF(J8,D8,IFERROR(B9-E9*(C9-B9)/(F9-E9),D8)) | E9: =B9+COS(B9) | F9: =C9+COS(C9) | G9: =D9+COS(D9) | H9: =ABS(D9-D8) | I9: =IF(ISNUMBER(G9),ABS(G9),"") | J9: =IF(OR(J8,AND(ISNUMBER(H9),H9<$B$4,I9<$B$4)),TRUE,FALSE) | K9: =IF(AND(J9,NOT(J8)),"<= KONVERGEN",IF(J9,"","lanjut"))
A10: 4 | B10: =IF(J9,B9,IF(SIGN(G9)=SIGN(E9),D9,B9)) | C10: =IF(J9,C9,IF(SIGN(G9)=SIGN(E9),C9,D9)) | D10: =IF(J9,D9,IFERROR(B10-E10*(C10-B10)/(F10-E10),D9)) | E10: =B10+COS(B10) | F10: =C10+COS(C10) | G10: =D10+COS(D10) | H10: =ABS(D10-D9) | I10: =IF(ISNUMBER(G10),ABS(G10),"") | J10: =IF(OR(J9,AND(ISNUMBER(H10),H10<$B$4,I10<$B$4)),TRUE,FALSE) | K10: =IF(AND(J10,NOT(J9)),"<= KONVERGEN",IF(J10,"","lanjut"))
A11: 5 | B11: =IF(J10,B10,IF(SIGN(G10)=SIGN(E10),D10,B10)) | C11: =IF(J10,C10,IF(SIGN(G10)=SIGN(E10),C10,D10)) | D11: =IF(J10,D10,IFERROR(B11-E11*(C11-B11)/(F11-E11),D10)) | E11: =B11+COS(B11) | F11: =C11+COS(C11) | G11: =D11+COS(D11) | H11: =ABS(D11-D10) | I11: =IF(ISNUMBER(G11),ABS(G11),"") | J11: =IF(OR(J10,AND(ISNUMBER(H11),H11<$B$4,I11<$B$4)),TRUE,FALSE) | K11: =IF(AND(J11,NOT(J10)),"<= KONVERGEN",IF(J11,"","lanjut"))
A12: 6 | B12: =IF(J11,B11,IF(SIGN(G11)=SIGN(E11),D11,B11)) | C12: =IF(J11,C11,IF(SIGN(G11)=SIGN(E11),C11,D11)) | D12: =IF(J11,D11,IFERROR(B12-E12*(C12-B12)/(F12-E12),D11)) | E12: =B12+COS(B12) | F12: =C12+COS(C12) | G12: =D12+COS(D12) | H12: =ABS(D12-D11) | I12: =IF(ISNUMBER(G12),ABS(G12),"") | J12: =IF(OR(J11,AND(ISNUMBER(H12),H12<$B$4,I12<$B$4)),TRUE,FALSE) | K12: =IF(AND(J12,NOT(J11)),"<= KONVERGEN",IF(J12,"","lanjut"))
A13: 7 | B13: =IF(J12,B12,IF(SIGN(G12)=SIGN(E12),D12,B12)) | C13: =IF(J12,C12,IF(SIGN(G12)=SIGN(E12),C12,D12)) | D13: =IF(J12,D12,IFERROR(B13-E13*(C13-B13)/(F13-E13),D12)) | E13: =B13+COS(B13) | F13: =C13+COS(C13) | G13: =D13+COS(D13) | H13: =ABS(D13-D12) | I13: =IF(ISNUMBER(G13),ABS(G13),"") | J13: =IF(OR(J12,AND(ISNUMBER(H13),H13<$B$4,I13<$B$4)),TRUE,FALSE) | K13: =IF(AND(J13,NOT(J12)),"<= KONVERGEN",IF(J13,"","lanjut"))
A14: 8 | B14: =IF(J13,B13,IF(SIGN(G13)=SIGN(E13),D13,B13)) | C14: =IF(J13,C13,IF(SIGN(G13)=SIGN(E13),C13,D13)) | D14: =IF(J13,D13,IFERROR(B14-E14*(C14-B14)/(F14-E14),D13)) | E14: =B14+COS(B14) | F14: =C14+COS(C14) | G14: =D14+COS(D14) | H14: =ABS(D14-D13) | I14: =IF(ISNUMBER(G14),ABS(G14),"") | J14: =IF(OR(J13,AND(ISNUMBER(H14),H14<$B$4,I14<$B$4)),TRUE,FALSE) | K14: =IF(AND(J14,NOT(J13)),"<= KONVERGEN",IF(J14,"","lanjut"))
A15: 9 | B15: =IF(J14,B14,IF(SIGN(G14)=SIGN(E14),D14,B14)) | C15: =IF(J14,C14,IF(SIGN(G14)=SIGN(E14),C14,D14)) | D15: =IF(J14,D14,IFERROR(B15-E15*(C15-B15)/(F15-E15),D14)) | E15: =B15+COS(B15) | F15: =C15+COS(C15) | G15: =D15+COS(D15) | H15: =ABS(D15-D14) | I15: =IF(ISNUMBER(G15),ABS(G15),"") | J15: =IF(OR(J14,AND(ISNUMBER(H15),H15<$B$4,I15<$B$4)),TRUE,FALSE) | K15: =IF(AND(J15,NOT(J14)),"<= KONVERGEN",IF(J15,"","lanjut"))
A16: 10 | B16: =IF(J15,B15,IF(SIGN(G15)=SIGN(E15),D15,B15)) | C16: =IF(J15,C15,IF(SIGN(G15)=SIGN(E15),C15,D15)) | D16: =IF(J15,D15,IFERROR(B16-E16*(C16-B16)/(F16-E16),D15)) | E16: =B16+COS(B16) | F16: =C16+COS(C16) | G16: =D16+COS(D16) | H16: =ABS(D16-D15) | I16: =IF(ISNUMBER(G16),ABS(G16),"") | J16: =IF(OR(J15,AND(ISNUMBER(H16),H16<$B$4,I16<$B$4)),TRUE,FALSE) | K16: =IF(AND(J16,NOT(J15)),"<= KONVERGEN",IF(J16,"","lanjut"))
A17: 11 | B17: =IF(J16,B16,IF(SIGN(G16)=SIGN(E16),D16,B16)) | C17: =IF(J16,C16,IF(SIGN(G16)=SIGN(E16),C16,D16)) | D17: =IF(J16,D16,IFERROR(B17-E17*(C17-B17)/(F17-E17),D16)) | E17: =B17+COS(B17) | F17: =C17+COS(C17) | G17: =D17+COS(D17) | H17: =ABS(D17-D16) | I17: =IF(ISNUMBER(G17),ABS(G17),"") | J17: =IF(OR(J16,AND(ISNUMBER(H17),H17<$B$4,I17<$B$4)),TRUE,FALSE) | K17: =IF(AND(J17,NOT(J16)),"<= KONVERGEN",IF(J17,"","lanjut"))
A18: 12 | B18: =IF(J17,B17,IF(SIGN(G17)=SIGN(E17),D17,B17)) | C18: =IF(J17,C17,IF(SIGN(G17)=SIGN(E17),C17,D17)) | D18: =IF(J17,D17,IFERROR(B18-E18*(C18-B18)/(F18-E18),D17)) | E18: =B18+COS(B18) | F18: =C18+COS(C18) | G18: =D18+COS(D18) | H18: =ABS(D18-D17) | I18: =IF(ISNUMBER(G18),ABS(G18),"") | J18: =IF(OR(J17,AND(ISNUMBER(H18),H18<$B$4,I18<$B$4)),TRUE,FALSE) | K18: =IF(AND(J18,NOT(J17)),"<= KONVERGEN",IF(J18,"","lanjut"))
A19: 13 | B19: =IF(J18,B18,IF(SIGN(G18)=SIGN(E18),D18,B18)) | C19: =IF(J18,C18,IF(SIGN(G18)=SIGN(E18),C18,D18)) | D19: =IF(J18,D18,IFERROR(B19-E19*(C19-B19)/(F19-E19),D18)) | E19: =B19+COS(B19) | F19: =C19+COS(C19) | G19: =D19+COS(D19) | H19: =ABS(D19-D18) | I19: =IF(ISNUMBER(G19),ABS(G19),"") | J19: =IF(OR(J18,AND(ISNUMBER(H19),H19<$B$4,I19<$B$4)),TRUE,FALSE) | K19: =IF(AND(J19,NOT(J18)),"<= KONVERGEN",IF(J19,"","lanjut"))
... A26: 20 | B26: =IF(J25,B25,IF(SIGN(G25)=SIGN(E25),D25,B25)) | C26: =IF(J25,C25,IF(SIGN(G25)=SIGN(E25),C25,D25)) | D26: =IF(J25,D25,IFERROR(B26-E26*(C26-B26)/(F26-E26),D25)) | E26: =B26+COS(B26) | F26: =C26+COS(C26) | G26: =D26+COS(D26) | H26: =ABS(D26-D25) | I26: =IF(ISNUMBER(G26),ABS(G26),"") | J26: =IF(OR(J25,AND(ISNUMBER(H26),H26<$B$4,I26<$B$4)),TRUE,FALSE) | K26: =IF(AND(J26,NOT(J25)),"<= KONVERGEN",IF(J26,"","lanjut"))
A28: Akar: | B28: =D26 | D28: f(akar): | E28: =G26
A29: Jumlah iterasi sampai konvergen: | D29: =IFERROR(MATCH(TRUE,J7:J26,0),"-")

Sheet Soal 7
A1: SOAL 7 - METODE REGULA FALSI
A2: f(x) = 2x - log x - 6 = 0 (log basis 10)
A3: Interval: | B3: a = | C3: 3 | D3: b = | E3: 3.5
A4: Toleransi: | B4: 0.001 | C4: berhenti bila |x(k) - x(k-1)| < tol dan |f(x)| < tol
A6: Iterasi k | B6: a | C6: b | D6: x(k) | E6: f(a) | F6: f(b) | G6: f(x(k)) | H6: |x(k)-x(k-1)| | I6: |f(x(k))| | J6: selesai? | K6: Status
A7: 1 | B7: =C3 | C7: =E3 | D7: =IFERROR(B7-E7*(C7-B7)/(F7-E7),"") | E7: =2*B7-LOG10(B7)-6 | F7: =2*C7-LOG10(C7)-6 | G7: =2*D7-LOG10(D7)-6 | I7: =IF(ISNUMBER(G7),ABS(G7),"") | J7: =IF(AND(ISNUMBER(H7),H7<$B$4,I7<$B$4),TRUE,FALSE) | K7: =IF(J7,"<= KONVERGEN","lanjut")
A8: 2 | B8: =IF(J7,B7,IF(SIGN(G7)=SIGN(E7),D7,B7)) | C8: =IF(J7,C7,IF(SIGN(G7)=SIGN(E7),C7,D7)) | D8: =IF(J7,D7,IFERROR(B8-E8*(C8-B8)/(F8-E8),D7)) | E8: =2*B8-LOG10(B8)-6 | F8: =2*C8-LOG10(C8)-6 | G8: =2*D8-LOG10(D8)-6 | H8: =ABS(D8-D7) | I8: =IF(ISNUMBER(G8),ABS(G8),"") | J8: =IF(OR(J7,AND(ISNUMBER(H8),H8<$B$4,I8<$B$4)),TRUE,FALSE) | K8: =IF(AND(J8,NOT(J7)),"<= KONVERGEN",IF(J8,"","lanjut"))
A9: 3 | B9: =IF(J8,B8,IF(SIGN(G8)=SIGN(E8),D8,B8)) | C9: =IF(J8,C8,IF(SIGN(G8)=SIGN(E8),C8,D8)) | D9: =IF(J8,D8,IFERROR(B9-E9*(C9-B9)/(F9-E9),D8)) | E9: =2*B9-LOG10(B9)-6 | F9: =2*C9-LOG10(C9)-6 | G9: =2*D9-LOG10(D9)-6 | H9: =ABS(D9-D8) | I9: =IF(ISNUMBER(G9),ABS(G9),"") | J9: =IF(OR(J8,AND(ISNUMBER(H9),H9<$B$4,I9<$B$4)),TRUE,FALSE) | K9: =IF(AND(J9,NOT(J8)),"<= KONVERGEN",IF(J9,"","lanjut"))
A10: 4 | B10: =IF(J9,B9,IF(SIGN(G9)=SIGN(E9),D9,B9)) | C10: =IF(J9,C9,IF(SIGN(G9)=SIGN(E9),C9,D9)) | D10: =IF(J9,D9,IFERROR(B10-E10*(C10-B10)/(F10-E10),D9)) | E10: =2*B10-LOG10(B10)-6 | F10: =2*C10-LOG10(C10)-6 | G10: =2*D10-LOG10(D10)-6 | H10: =ABS(D10-D9) | I10: =IF(ISNUMBER(G10),ABS(G10),"") | J10: =IF(OR(J9,AND(ISNUMBER(H10),H10<$B$4,I10<$B$4)),TRUE,FALSE) | K10: =IF(AND(J10,NOT(J9)),"<= KONVERGEN",IF(J10,"","lanjut"))
A11: 5 | B11: =IF(J10,B10,IF(SIGN(G10)=SIGN(E10),D10,B10)) | C11: =IF(J10,C10,IF(SIGN(G10)=SIGN(E10),C10,D10)) | D11: =IF(J10,D10,IFERROR(B11-E11*(C11-B11)/(F11-E11),D10)) | E11: =2*B11-LOG10(B11)-6 | F11: =2*C11-LOG10(C11)-6 | G11: =2*D11-LOG10(D11)-6 | H11: =ABS(D11-D10) | I11: =IF(ISNUMBER(G11),ABS(G11),"") | J11: =IF(OR(J10,AND(ISNUMBER(H11),H11<$B$4,I11<$B$4)),TRUE,FALSE) | K11: =IF(AND(J11,NOT(J10)),"<= KONVERGEN",IF(J11,"","lanjut"))
A12: 6 | B12: =IF(J11,B11,IF(SIGN(G11)=SIGN(E11),D11,B11)) | C12: =IF(J11,C11,IF(SIGN(G11)=SIGN(E11),C11,D11)) | D12: =IF(J11,D11,IFERROR(B12-E12*(C12-B12)/(F12-E12),D11)) | E12: =2*B12-LOG10(B12)-6 | F12: =2*C12-LOG10(C12)-6 | G12: =2*D12-LOG10(D12)-6 | H12: =ABS(D12-D11) | I12: =IF(ISNUMBER(G12),ABS(G12),"") | J12: =IF(OR(J11,AND(ISNUMBER(H12),H12<$B$4,I12<$B$4)),TRUE,FALSE) | K12: =IF(AND(J12,NOT(J11)),"<= KONVERGEN",IF(J12,"","lanjut"))
A13: 7 | B13: =IF(J12,B12,IF(SIGN(G12)=SIGN(E12),D12,B12)) | C13: =IF(J12,C12,IF(SIGN(G12)=SIGN(E12),C12,D12)) | D13: =IF(J12,D12,IFERROR(B13-E13*(C13-B13)/(F13-E13),D12)) | E13: =2*B13-LOG10(B13)-6 | F13: =2*C13-LOG10(C13)-6 | G13: =2*D13-LOG10(D13)-6 | H13: =ABS(D13-D12) | I13: =IF(ISNUMBER(G13),ABS(G13),"") | J13: =IF(OR(J12,AND(ISNUMBER(H13),H13<$B$4,I13<$B$4)),TRUE,FALSE) | K13: =IF(AND(J13,NOT(J12)),"<= KONVERGEN",IF(J13,"","lanjut"))
A14: 8 | B14: =IF(J13,B13,IF(SIGN(G13)=SIGN(E13),D13,B13)) | C14: =IF(J13,C13,IF(SIGN(G13)=SIGN(E13),C13,D13)) | D14: =IF(J13,D13,IFERROR(B14-E14*(C14-B14)/(F14-E14),D13)) | E14: =2*B14-LOG10(B14)-6 | F14: =2*C14-LOG10(C14)-6 | G14: =2*D14-LOG10(D14)-6 | H14: =ABS(D14-D13) | I14: =IF(ISNUMBER(G14),ABS(G14),"") | J14: =IF(OR(J13,AND(ISNUMBER(H14),H14<$B$4,I14<$B$4)),TRUE,FALSE) | K14: =IF(AND(J14,NOT(J13)),"<= KONVERGEN",IF(J14,"","lanjut"))
A15: 9 | B15: =IF(J14,B14,IF(SIGN(G14)=SIGN(E14),D14,B14)) | C15: =IF(J14,C14,IF(SIGN(G14)=SIGN(E14),C14,D14)) | D15: =IF(J14,D14,IFERROR(B15-E15*(C15-B15)/(F15-E15),D14)) | E15: =2*B15-LOG10(B15)-6 | F15: =2*C15-LOG10(C15)-6 | G15: =2*D15-LOG10(D15)-6 | H15: =ABS(D15-D14) | I15: =IF(ISNUMBER(G15),ABS(G15),"") | J15: =IF(OR(J14,AND(ISNUMBER(H15),H15<$B$4,I15<$B$4)),TRUE,FALSE) | K15: =IF(AND(J15,NOT(J14)),"<= KONVERGEN",IF(J15,"","lanjut"))
A16: 10 | B16: =IF(J15,B15,IF(SIGN(G15)=SIGN(E15),D15,B15)) | C16: =IF(J15,C15,IF(SIGN(G15)=SIGN(E15),C15,D15)) | D16: =IF(J15,D15,IFERROR(B16-E16*(C16-B16)/(F16-E16),D15)) | E16: =2*B16-LOG10(B16)-6 | F16: =2*C16-LOG10(C16)-6 | G16: =2*D16-LOG10(D16)-6 | H16: =ABS(D16-D15) | I16: =IF(ISNUMBER(G16),ABS(G16),"") | J16: =IF(OR(J15,AND(ISNUMBER(H16),H16<$B$4,I16<$B$4)),TRUE,FALSE) | K16: =IF(AND(J16,NOT(J15)),"<= KONVERGEN",IF(J16,"","lanjut"))
A17: 11 | B17: =IF(J16,B16,IF(SIGN(G16)=SIGN(E16),D16,B16)) | C17: =IF(J16,C16,IF(SIGN(G16)=SIGN(E16),C16,D16)) | D17: =IF(J16,D16,IFERROR(B17-E17*(C17-B17)/(F17-E17),D16)) | E17: =2*B17-LOG10(B17)-6 | F17: =2*C17-LOG10(C17)-6 | G17: =2*D17-LOG10(D17)-6 | H17: =ABS(D17-D16) | I17: =IF(ISNUMBER(G17),ABS(G17),"") | J17: =IF(OR(J16,AND(ISNUMBER(H17),H17<$B$4,I17<$B$4)),TRUE,FALSE) | K17: =IF(AND(J17,NOT(J16)),"<= KONVERGEN",IF(J17,"","lanjut"))
A18: 12 | B18: =IF(J17,B17,IF(SIGN(G17)=SIGN(E17),D17,B17)) | C18: =IF(J17,C17,IF(SIGN(G17)=SIGN(E17),C17,D17)) | D18: =IF(J17,D17,IFERROR(B18-E18*(C18-B18)/(F18-E18),D17)) | E18: =2*B18-LOG10(B18)-6 | F18: =2*C18-LOG10(C18)-6 | G18: =2*D18-LOG10(D18)-6 | H18: =ABS(D18-D17) | I18: =IF(ISNUMBER(G18),ABS(G18),"") | J18: =IF(OR(J17,AND(ISNUMBER(H18),H18<$B$4,I18<$B$4)),TRUE,FALSE) | K18: =IF(AND(J18,NOT(J17)),"<= KONVERGEN",IF(J18,"","lanjut"))
A19: 13 | B19: =IF(J18,B18,IF(SIGN(G18)=SIGN(E18),D18,B18)) | C19: =IF(J18,C18,IF(SIGN(G18)=SIGN(E18),C18,D18)) | D19: =IF(J18,D18,IFERROR(B19-E19*(C19-B19)/(F19-E19),D18)) | E19: =2*B19-LOG10(B19)-6 | F19: =2*C19-LOG10(C19)-6 | G19: =2*D19-LOG10(D19)-6 | H19: =ABS(D19-D18) | I19: =IF(ISNUMBER(G19),ABS(G19),"") | J19: =IF(OR(J18,AND(ISNUMBER(H19),H19<$B$4,I19<$B$4)),TRUE,FALSE) | K19: =IF(AND(J19,NOT(J18)),"<= KONVERGEN",IF(J19,"","lanjut"))
... A26: 20 | B26: =IF(J25,B25,IF(SIGN(G25)=SIGN(E25),D25,B25)) | C26: =IF(J25,C25,IF(SIGN(G25)=SIGN(E25),C25,D25)) | D26: =IF(J25,D25,IFERROR(B26-E26*(C26-B26)/(F26-E26),D25)) | E26: =2*B26-LOG10(B26)-6 | F26: =2*C26-LOG10(C26)-6 | G26: =2*D26-LOG10(D26)-6 | H26: =ABS(D26-D25) | I26: =IF(ISNUMBER(G26),ABS(G26),"") | J26: =IF(OR(J25,AND(ISNUMBER(H26),H26<$B$4,I26<$B$4)),TRUE,FALSE) | K26: =IF(AND(J26,NOT(J25)),"<= KONVERGEN",IF(J26,"","lanjut"))
A28: Akar: | B28: =D26 | D28: f(akar): | E28: =G26
A29: Jumlah iterasi sampai konvergen: | D29: =IFERROR(MATCH(TRUE,J7:J26,0),"-")

Sheet Soal 8
A1: SOAL 8 - METODE REGULA FALSI
A2: f(x) = x^6 - x^4 - x^3 - 1 = 0
A3: Interval: | B3: a = | C3: 1 | D3: b = | E3: 1.5
A4: Toleransi: | B4: 0.001 | C4: berhenti bila |x(k) - x(k-1)| < tol dan |f(x)| < tol
A6: Iterasi k | B6: a | C6: b | D6: x(k) | E6: f(a) | F6: f(b) | G6: f(x(k)) | H6: |x(k)-x(k-1)| | I6: |f(x(k))| | J6: selesai? | K6: Status
A7: 1 | B7: =C3 | C7: =E3 | D7: =IFERROR(B7-E7*(C7-B7)/(F7-E7),"") | E7: =B7^6-B7^4-B7^3-1 | F7: =C7^6-C7^4-C7^3-1 | G7: =D7^6-D7^4-D7^3-1 | I7: =IF(ISNUMBER(G7),ABS(G7),"") | J7: =IF(AND(ISNUMBER(H7),H7<$B$4,I7<$B$4),TRUE,FALSE) | K7: =IF(J7,"<= KONVERGEN","lanjut")
A8: 2 | B8: =IF(J7,B7,IF(SIGN(G7)=SIGN(E7),D7,B7)) | C8: =IF(J7,C7,IF(SIGN(G7)=SIGN(E7),C7,D7)) | D8: =IF(J7,D7,IFERROR(B8-E8*(C8-B8)/(F8-E8),D7)) | E8: =B8^6-B8^4-B8^3-1 | F8: =C8^6-C8^4-C8^3-1 | G8: =D8^6-D8^4-D8^3-1 | H8: =ABS(D8-D7) | I8: =IF(ISNUMBER(G8),ABS(G8),"") | J8: =IF(OR(J7,AND(ISNUMBER(H8),H8<$B$4,I8<$B$4)),TRUE,FALSE) | K8: =IF(AND(J8,NOT(J7)),"<= KONVERGEN",IF(J8,"","lanjut"))
A9: 3 | B9: =IF(J8,B8,IF(SIGN(G8)=SIGN(E8),D8,B8)) | C9: =IF(J8,C8,IF(SIGN(G8)=SIGN(E8),C8,D8)) | D9: =IF(J8,D8,IFERROR(B9-E9*(C9-B9)/(F9-E9),D8)) | E9: =B9^6-B9^4-B9^3-1 | F9: =C9^6-C9^4-C9^3-1 | G9: =D9^6-D9^4-D9^3-1 | H9: =ABS(D9-D8) | I9: =IF(ISNUMBER(G9),ABS(G9),"") | J9: =IF(OR(J8,AND(ISNUMBER(H9),H9<$B$4,I9<$B$4)),TRUE,FALSE) | K9: =IF(AND(J9,NOT(J8)),"<= KONVERGEN",IF(J9,"","lanjut"))
A10: 4 | B10: =IF(J9,B9,IF(SIGN(G9)=SIGN(E9),D9,B9)) | C10: =IF(J9,C9,IF(SIGN(G9)=SIGN(E9),C9,D9)) | D10: =IF(J9,D9,IFERROR(B10-E10*(C10-B10)/(F10-E10),D9)) | E10: =B10^6-B10^4-B10^3-1 | F10: =C10^6-C10^4-C10^3-1 | G10: =D10^6-D10^4-D10^3-1 | H10: =ABS(D10-D9) | I10: =IF(ISNUMBER(G10),ABS(G10),"") | J10: =IF(OR(J9,AND(ISNUMBER(H10),H10<$B$4,I10<$B$4)),TRUE,FALSE) | K10: =IF(AND(J10,NOT(J9)),"<= KONVERGEN",IF(J10,"","lanjut"))
A11: 5 | B11: =IF(J10,B10,IF(SIGN(G10)=SIGN(E10),D10,B10)) | C11: =IF(J10,C10,IF(SIGN(G10)=SIGN(E10),C10,D10)) | D11: =IF(J10,D10,IFERROR(B11-E11*(C11-B11)/(F11-E11),D10)) | E11: =B11^6-B11^4-B11^3-1 | F11: =C11^6-C11^4-C11^3-1 | G11: =D11^6-D11^4-D11^3-1 | H11: =ABS(D11-D10) | I11: =IF(ISNUMBER(G11),ABS(G11),"") | J11: =IF(OR(J10,AND(ISNUMBER(H11),H11<$B$4,I11<$B$4)),TRUE,FALSE) | K11: =IF(AND(J11,NOT(J10)),"<= KONVERGEN",IF(J11,"","lanjut"))
A12: 6 | B12: =IF(J11,B11,IF(SIGN(G11)=SIGN(E11),D11,B11)) | C12: =IF(J11,C11,IF(SIGN(G11)=SIGN(E11),C11,D11)) | D12: =IF(J11,D11,IFERROR(B12-E12*(C12-B12)/(F12-E12),D11)) | E12: =B12^6-B12^4-B12^3-1 | F12: =C12^6-C12^4-C12^3-1 | G12: =D12^6-D12^4-D12^3-1 | H12: =ABS(D12-D11) | I12: =IF(ISNUMBER(G12),ABS(G12),"") | J12: =IF(OR(J11,AND(ISNUMBER(H12),H12<$B$4,I12<$B$4)),TRUE,FALSE) | K12: =IF(AND(J12,NOT(J11)),"<= KONVERGEN",IF(J12,"","lanjut"))
A13: 7 | B13: =IF(J12,B12,IF(SIGN(G12)=SIGN(E12),D12,B12)) | C13: =IF(J12,C12,IF(SIGN(G12)=SIGN(E12),C12,D12)) | D13: =IF(J12,D12,IFERROR(B13-E13*(C13-B13)/(F13-E13),D12)) | E13: =B13^6-B13^4-B13^3-1 | F13: =C13^6-C13^4-C13^3-1 | G13: =D13^6-D13^4-D13^3-1 | H13: =ABS(D13-D12) | I13: =IF(ISNUMBER(G13),ABS(G13),"") | J13: =IF(OR(J12,AND(ISNUMBER(H13),H13<$B$4,I13<$B$4)),TRUE,FALSE) | K13: =IF(AND(J13,NOT(J12)),"<= KONVERGEN",IF(J13,"","lanjut"))
A14: 8 | B14: =IF(J13,B13,IF(SIGN(G13)=SIGN(E13),D13,B13)) | C14: =IF(J13,C13,IF(SIGN(G13)=SIGN(E13),C13,D13)) | D14: =IF(J13,D13,IFERROR(B14-E14*(C14-B14)/(F14-E14),D13)) | E14: =B14^6-B14^4-B14^3-1 | F14: =C14^6-C14^4-C14^3-1 | G14: =D14^6-D14^4-D14^3-1 | H14: =ABS(D14-D13) | I14: =IF(ISNUMBER(G14),ABS(G14),"") | J14: =IF(OR(J13,AND(ISNUMBER(H14),H14<$B$4,I14<$B$4)),TRUE,FALSE) | K14: =IF(AND(J14,NOT(J13)),"<= KONVERGEN",IF(J14,"","lanjut"))
A15: 9 | B15: =IF(J14,B14,IF(SIGN(G14)=SIGN(E14),D14,B14)) | C15: =IF(J14,C14,IF(SIGN(G14)=SIGN(E14),C14,D14)) | D15: =IF(J14,D14,IFERROR(B15-E15*(C15-B15)/(F15-E15),D14)) | E15: =B15^6-B15^4-B15^3-1 | F15: =C15^6-C15^4-C15^3-1 | G15: =D15^6-D15^4-D15^3-1 | H15: =ABS(D15-D14) | I15: =IF(ISNUMBER(G15),ABS(G15),"") | J15: =IF(OR(J14,AND(ISNUMBER(H15),H15<$B$4,I15<$B$4)),TRUE,FALSE) | K15: =IF(AND(J15,NOT(J14)),"<= KONVERGEN",IF(J15,"","lanjut"))
A16: 10 | B16: =IF(J15,B15,IF(SIGN(G15)=SIGN(E15),D15,B15)) | C16: =IF(J15,C15,IF(SIGN(G15)=SIGN(E15),C15,D15)) | D16: =IF(J15,D15,IFERROR(B16-E16*(C16-B16)/(F16-E16),D15)) | E16: =B16^6-B16^4-B16^3-1 | F16: =C16^6-C16^4-C16^3-1 | G16: =D16^6-D16^4-D16^3-1 | H16: =ABS(D16-D15) | I16: =IF(ISNUMBER(G16),ABS(G16),"") | J16: =IF(OR(J15,AND(ISNUMBER(H16),H16<$B$4,I16<$B$4)),TRUE,FALSE) | K16: =IF(AND(J16,NOT(J15)),"<= KONVERGEN",IF(J16,"","lanjut"))
A17: 11 | B17: =IF(J16,B16,IF(SIGN(G16)=SIGN(E16),D16,B16)) | C17: =IF(J16,C16,IF(SIGN(G16)=SIGN(E16),C16,D16)) | D17: =IF(J16,D16,IFERROR(B17-E17*(C17-B17)/(F17-E17),D16)) | E17: =B17^6-B17^4-B17^3-1 | F17: =C17^6-C17^4-C17^3-1 | G17: =D17^6-D17^4-D17^3-1 | H17: =ABS(D17-D16) | I17: =IF(ISNUMBER(G17),ABS(G17),"") | J17: =IF(OR(J16,AND(ISNUMBER(H17),H17<$B$4,I17<$B$4)),TRUE,FALSE) | K17: =IF(AND(J17,NOT(J16)),"<= KONVERGEN",IF(J17,"","lanjut"))
A18: 12 | B18: =IF(J17,B17,IF(SIGN(G17)=SIGN(E17),D17,B17)) | C18: =IF(J17,C17,IF(SIGN(G17)=SIGN(E17),C17,D17)) | D18: =IF(J17,D17,IFERROR(B18-E18*(C18-B18)/(F18-E18),D17)) | E18: =B18^6-B18^4-B18^3-1 | F18: =C18^6-C18^4-C18^3-1 | G18: =D18^6-D18^4-D18^3-1 | H18: =ABS(D18-D17) | I18: =IF(ISNUMBER(G18),ABS(G18),"") | J18: =IF(OR(J17,AND(ISNUMBER(H18),H18<$B$4,I18<$B$4)),TRUE,FALSE) | K18: =IF(AND(J18,NOT(J17)),"<= KONVERGEN",IF(J18,"","lanjut"))
A19: 13 | B19: =IF(J18,B18,IF(SIGN(G18)=SIGN(E18),D18,B18)) | C19: =IF(J18,C18,IF(SIGN(G18)=SIGN(E18),C18,D18)) | D19: =IF(J18,D18,IFERROR(B19-E19*(C19-B19)/(F19-E19),D18)) | E19: =B19^6-B19^4-B19^3-1 | F19: =C19^6-C19^4-C19^3-1 | G19: =D19^6-D19^4-D19^3-1 | H19: =ABS(D19-D18) | I19: =IF(ISNUMBER(G19),ABS(G19),"") | J19: =IF(OR(J18,AND(ISNUMBER(H19),H19<$B$4,I19<$B$4)),TRUE,FALSE) | K19: =IF(AND(J19,NOT(J18)),"<= KONVERGEN",IF(J19,"","lanjut"))
... A26: 20 | B26: =IF(J25,B25,IF(SIGN(G25)=SIGN(E25),D25,B25)) | C26: =IF(J25,C25,IF(SIGN(G25)=SIGN(E25),C25,D25)) | D26: =IF(J25,D25,IFERROR(B26-E26*(C26-B26)/(F26-E26),D25)) | E26: =B26^6-B26^4-B26^3-1 | F26: =C26^6-C26^4-C26^3-1 | G26: =D26^6-D26^4-D26^3-1 | H26: =ABS(D26-D25) | I26: =IF(ISNUMBER(G26),ABS(G26),"") | J26: =IF(OR(J25,AND(ISNUMBER(H26),H26<$B$4,I26<$B$4)),TRUE,FALSE) | K26: =IF(AND(J26,NOT(J25)),"<= KONVERGEN",IF(J26,"","lanjut"))
A28: Akar: | B28: =D26 | D28: f(akar): | E28: =G26
A29: Jumlah iterasi sampai konvergen: | D29: =IFERROR(MATCH(TRUE,J7:J26,0),"-")

Sheet Soal 9
A1: SOAL 9 - METODE REGULA FALSI
A2: f(x) = x - e^(-x) = 0
A3: Interval: | B3: a = | C3: 0 | D3: b = | E3: 1
A4: Toleransi: | B4: 0.001 | C4: berhenti bila |x(k) - x(k-1)| < tol dan |f(x)| < tol
A6: Iterasi k | B6: a | C6: b | D6: x(k) | E6: f(a) | F6: f(b) | G6: f(x(k)) | H6: |x(k)-x(k-1)| | I6: |f(x(k))| | J6: selesai? | K6: Status
A7: 1 | B7: =C3 | C7: =E3 | D7: =IFERROR(B7-E7*(C7-B7)/(F7-E7),"") | E7: =B7-EXP(-B7) | F7: =C7-EXP(-C7) | G7: =D7-EXP(-D7) | I7: =IF(ISNUMBER(G7),ABS(G7),"") | J7: =IF(AND(ISNUMBER(H7),H7<$B$4,I7<$B$4),TRUE,FALSE) | K7: =IF(J7,"<= KONVERGEN","lanjut")
A8: 2 | B8: =IF(J7,B7,IF(SIGN(G7)=SIGN(E7),D7,B7)) | C8: =IF(J7,C7,IF(SIGN(G7)=SIGN(E7),C7,D7)) | D8: =IF(J7,D7,IFERROR(B8-E8*(C8-B8)/(F8-E8),D7)) | E8: =B8-EXP(-B8) | F8: =C8-EXP(-C8) | G8: =D8-EXP(-D8) | H8: =ABS(D8-D7) | I8: =IF(ISNUMBER(G8),ABS(G8),"") | J8: =IF(OR(J7,AND(ISNUMBER(H8),H8<$B$4,I8<$B$4)),TRUE,FALSE) | K8: =IF(AND(J8,NOT(J7)),"<= KONVERGEN",IF(J8,"","lanjut"))
A9: 3 | B9: =IF(J8,B8,IF(SIGN(G8)=SIGN(E8),D8,B8)) | C9: =IF(J8,C8,IF(SIGN(G8)=SIGN(E8),C8,D8)) | D9: =IF(J8,D8,IFERROR(B9-E9*(C9-B9)/(F9-E9),D8)) | E9: =B9-EXP(-B9) | F9: =C9-EXP(-C9) | G9: =D9-EXP(-D9) | H9: =ABS(D9-D8) | I9: =IF(ISNUMBER(G9),ABS(G9),"") | J9: =IF(OR(J8,AND(ISNUMBER(H9),H9<$B$4,I9<$B$4)),TRUE,FALSE) | K9: =IF(AND(J9,NOT(J8)),"<= KONVERGEN",IF(J9,"","lanjut"))
A10: 4 | B10: =IF(J9,B9,IF(SIGN(G9)=SIGN(E9),D9,B9)) | C10: =IF(J9,C9,IF(SIGN(G9)=SIGN(E9),C9,D9)) | D10: =IF(J9,D9,IFERROR(B10-E10*(C10-B10)/(F10-E10),D9)) | E10: =B10-EXP(-B10) | F10: =C10-EXP(-C10) | G10: =D10-EXP(-D10) | H10: =ABS(D10-D9) | I10: =IF(ISNUMBER(G10),ABS(G10),"") | J10: =IF(OR(J9,AND(ISNUMBER(H10),H10<$B$4,I10<$B$4)),TRUE,FALSE) | K10: =IF(AND(J10,NOT(J9)),"<= KONVERGEN",IF(J10,"","lanjut"))
A11: 5 | B11: =IF(J10,B10,IF(SIGN(G10)=SIGN(E10),D10,B10)) | C11: =IF(J10,C10,IF(SIGN(G10)=SIGN(E10),C10,D10)) | D11: =IF(J10,D10,IFERROR(B11-E11*(C11-B11)/(F11-E11),D10)) | E11: =B11-EXP(-B11) | F11: =C11-EXP(-C11) | G11: =D11-EXP(-D11) | H11: =ABS(D11-D10) | I11: =IF(ISNUMBER(G11),ABS(G11),"") | J11: =IF(OR(J10,AND(ISNUMBER(H11),H11<$B$4,I11<$B$4)),TRUE,FALSE) | K11: =IF(AND(J11,NOT(J10)),"<= KONVERGEN",IF(J11,"","lanjut"))
A12: 6 | B12: =IF(J11,B11,IF(SIGN(G11)=SIGN(E11),D11,B11)) | C12: =IF(J11,C11,IF(SIGN(G11)=SIGN(E11),C11,D11)) | D12: =IF(J11,D11,IFERROR(B12-E12*(C12-B12)/(F12-E12),D11)) | E12: =B12-EXP(-B12) | F12: =C12-EXP(-C12) | G12: =D12-EXP(-D12) | H12: =ABS(D12-D11) | I12: =IF(ISNUMBER(G12),ABS(G12),"") | J12: =IF(OR(J11,AND(ISNUMBER(H12),H12<$B$4,I12<$B$4)),TRUE,FALSE) | K12: =IF(AND(J12,NOT(J11)),"<= KONVERGEN",IF(J12,"","lanjut"))
A13: 7 | B13: =IF(J12,B12,IF(SIGN(G12)=SIGN(E12),D12,B12)) | C13: =IF(J12,C12,IF(SIGN(G12)=SIGN(E12),C12,D12)) | D13: =IF(J12,D12,IFERROR(B13-E13*(C13-B13)/(F13-E13),D12)) | E13: =B13-EXP(-B13) | F13: =C13-EXP(-C13) | G13: =D13-EXP(-D13) | H13: =ABS(D13-D12) | I13: =IF(ISNUMBER(G13),ABS(G13),"") | J13: =IF(OR(J12,AND(ISNUMBER(H13),H13<$B$4,I13<$B$4)),TRUE,FALSE) | K13: =IF(AND(J13,NOT(J12)),"<= KONVERGEN",IF(J13,"","lanjut"))
A14: 8 | B14: =IF(J13,B13,IF(SIGN(G13)=SIGN(E13),D13,B13)) | C14: =IF(J13,C13,IF(SIGN(G13)=SIGN(E13),C13,D13)) | D14: =IF(J13,D13,IFERROR(B14-E14*(C14-B14)/(F14-E14),D13)) | E14: =B14-EXP(-B14) | F14: =C14-EXP(-C14) | G14: =D14-EXP(-D14) | H14: =ABS(D14-D13) | I14: =IF(ISNUMBER(G14),ABS(G14),"") | J14: =IF(OR(J13,AND(ISNUMBER(H14),H14<$B$4,I14<$B$4)),TRUE,FALSE) | K14: =IF(AND(J14,NOT(J13)),"<= KONVERGEN",IF(J14,"","lanjut"))
A15: 9 | B15: =IF(J14,B14,IF(SIGN(G14)=SIGN(E14),D14,B14)) | C15: =IF(J14,C14,IF(SIGN(G14)=SIGN(E14),C14,D14)) | D15: =IF(J14,D14,IFERROR(B15-E15*(C15-B15)/(F15-E15),D14)) | E15: =B15-EXP(-B15) | F15: =C15-EXP(-C15) | G15: =D15-EXP(-D15) | H15: =ABS(D15-D14) | I15: =IF(ISNUMBER(G15),ABS(G15),"") | J15: =IF(OR(J14,AND(ISNUMBER(H15),H15<$B$4,I15<$B$4)),TRUE,FALSE) | K15: =IF(AND(J15,NOT(J14)),"<= KONVERGEN",IF(J15,"","lanjut"))
A16: 10 | B16: =IF(J15,B15,IF(SIGN(G15)=SIGN(E15),D15,B15)) | C16: =IF(J15,C15,IF(SIGN(G15)=SIGN(E15),C15,D15)) | D16: =IF(J15,D15,IFERROR(B16-E16*(C16-B16)/(F16-E16),D15)) | E16: =B16-EXP(-B16) | F16: =C16-EXP(-C16) | G16: =D16-EXP(-D16) | H16: =ABS(D16-D15) | I16: =IF(ISNUMBER(G16),ABS(G16),"") | J16: =IF(OR(J15,AND(ISNUMBER(H16),H16<$B$4,I16<$B$4)),TRUE,FALSE) | K16: =IF(AND(J16,NOT(J15)),"<= KONVERGEN",IF(J16,"","lanjut"))
A17: 11 | B17: =IF(J16,B16,IF(SIGN(G16)=SIGN(E16),D16,B16)) | C17: =IF(J16,C16,IF(SIGN(G16)=SIGN(E16),C16,D16)) | D17: =IF(J16,D16,IFERROR(B17-E17*(C17-B17)/(F17-E17),D16)) | E17: =B17-EXP(-B17) | F17: =C17-EXP(-C17) | G17: =D17-EXP(-D17) | H17: =ABS(D17-D16) | I17: =IF(ISNUMBER(G17),ABS(G17),"") | J17: =IF(OR(J16,AND(ISNUMBER(H17),H17<$B$4,I17<$B$4)),TRUE,FALSE) | K17: =IF(AND(J17,NOT(J16)),"<= KONVERGEN",IF(J17,"","lanjut"))
A18: 12 | B18: =IF(J17,B17,IF(SIGN(G17)=SIGN(E17),D17,B17)) | C18: =IF(J17,C17,IF(SIGN(G17)=SIGN(E17),C17,D17)) | D18: =IF(J17,D17,IFERROR(B18-E18*(C18-B18)/(F18-E18),D17)) | E18: =B18-EXP(-B18) | F18: =C18-EXP(-C18) | G18: =D18-EXP(-D18) | H18: =ABS(D18-D17) | I18: =IF(ISNUMBER(G18),ABS(G18),"") | J18: =IF(OR(J17,AND(ISNUMBER(H18),H18<$B$4,I18<$B$4)),TRUE,FALSE) | K18: =IF(AND(J18,NOT(J17)),"<= KONVERGEN",IF(J18,"","lanjut"))
A19: 13 | B19: =IF(J18,B18,IF(SIGN(G18)=SIGN(E18),D18,B18)) | C19: =IF(J18,C18,IF(SIGN(G18)=SIGN(E18),C18,D18)) | D19: =IF(J18,D18,IFERROR(B19-E19*(C19-B19)/(F19-E19),D18)) | E19: =B19-EXP(-B19) | F19: =C19-EXP(-C19) | G19: =D19-EXP(-D19) | H19: =ABS(D19-D18) | I19: =IF(ISNUMBER(G19),ABS(G19),"") | J19: =IF(OR(J18,AND(ISNUMBER(H19),H19<$B$4,I19<$B$4)),TRUE,FALSE) | K19: =IF(AND(J19,NOT(J18)),"<= KONVERGEN",IF(J19,"","lanjut"))
... A26: 20 | B26: =IF(J25,B25,IF(SIGN(G25)=SIGN(E25),D25,B25)) | C26: =IF(J25,C25,IF(SIGN(G25)=SIGN(E25),C25,D25)) | D26: =IF(J25,D25,IFERROR(B26-E26*(C26-B26)/(F26-E26),D25)) | E26: =B26-EXP(-B26) | F26: =C26-EXP(-C26) | G26: =D26-EXP(-D26) | H26: =ABS(D26-D25) | I26: =IF(ISNUMBER(G26),ABS(G26),"") | J26: =IF(OR(J25,AND(ISNUMBER(H26),H26<$B$4,I26<$B$4)),TRUE,FALSE) | K26: =IF(AND(J26,NOT(J25)),"<= KONVERGEN",IF(J26,"","lanjut"))
A28: Akar: | B28: =D26 | D28: f(akar): | E28: =G26
A29: Jumlah iterasi sampai konvergen: | D29: =IFERROR(MATCH(TRUE,J7:J26,0),"-")

Sheet Soal 10
A1: SOAL 10 - METODE REGULA FALSI
A2: f(x) = ln[(1 + x)/(1 - x^2)] = 0
A3: Interval: | B3: a = | C3: -0.5 | D3: b = | E3: 0.5
A4: Toleransi: | B4: 0.001 | C4: berhenti bila |x(k) - x(k-1)| < tol dan |f(x)| < tol
A6: Iterasi k | B6: a | C6: b | D6: x(k) | E6: f(a) | F6: f(b) | G6: f(x(k)) | H6: |x(k)-x(k-1)| | I6: |f(x(k))| | J6: selesai? | K6: Status
A7: 1 | B7: =C3 | C7: =E3 | D7: =IFERROR(B7-E7*(C7-B7)/(F7-E7),"") | E7: =LN((1+B7)/(1-B7^2)) | F7: =LN((1+C7)/(1-C7^2)) | G7: =LN((1+D7)/(1-D7^2)) | I7: =IF(ISNUMBER(G7),ABS(G7),"") | J7: =IF(AND(ISNUMBER(H7),H7<$B$4,I7<$B$4),TRUE,FALSE) | K7: =IF(J7,"<= KONVERGEN","lanjut")
A8: 2 | B8: =IF(J7,B7,IF(SIGN(G7)=SIGN(E7),D7,B7)) | C8: =IF(J7,C7,IF(SIGN(G7)=SIGN(E7),C7,D7)) | D8: =IF(J7,D7,IFERROR(B8-E8*(C8-B8)/(F8-E8),D7)) | E8: =LN((1+B8)/(1-B8^2)) | F8: =LN((1+C8)/(1-C8^2)) | G8: =LN((1+D8)/(1-D8^2)) | H8: =ABS(D8-D7) | I8: =IF(ISNUMBER(G8),ABS(G8),"") | J8: =IF(OR(J7,AND(ISNUMBER(H8),H8<$B$4,I8<$B$4)),TRUE,FALSE) | K8: =IF(AND(J8,NOT(J7)),"<= KONVERGEN",IF(J8,"","lanjut"))
A9: 3 | B9: =IF(J8,B8,IF(SIGN(G8)=SIGN(E8),D8,B8)) | C9: =IF(J8,C8,IF(SIGN(G8)=SIGN(E8),C8,D8)) | D9: =IF(J8,D8,IFERROR(B9-E9*(C9-B9)/(F9-E9),D8)) | E9: =LN((1+B9)/(1-B9^2)) | F9: =LN((1+C9)/(1-C9^2)) | G9: =LN((1+D9)/(1-D9^2)) | H9: =ABS(D9-D8) | I9: =IF(ISNUMBER(G9),ABS(G9),"") | J9: =IF(OR(J8,AND(ISNUMBER(H9),H9<$B$4,I9<$B$4)),TRUE,FALSE) | K9: =IF(AND(J9,NOT(J8)),"<= KONVERGEN",IF(J9,"","lanjut"))
A10: 4 | B10: =IF(J9,B9,IF(SIGN(G9)=SIGN(E9),D9,B9)) | C10: =IF(J9,C9,IF(SIGN(G9)=SIGN(E9),C9,D9)) | D10: =IF(J9,D9,IFERROR(B10-E10*(C10-B10)/(F10-E10),D9)) | E10: =LN((1+B10)/(1-B10^2)) | F10: =LN((1+C10)/(1-C10^2)) | G10: =LN((1+D10)/(1-D10^2)) | H10: =ABS(D10-D9) | I10: =IF(ISNUMBER(G10),ABS(G10),"") | J10: =IF(OR(J9,AND(ISNUMBER(H10),H10<$B$4,I10<$B$4)),TRUE,FALSE) | K10: =IF(AND(J10,NOT(J9)),"<= KONVERGEN",IF(J10,"","lanjut"))
A11: 5 | B11: =IF(J10,B10,IF(SIGN(G10)=SIGN(E10),D10,B10)) | C11: =IF(J10,C10,IF(SIGN(G10)=SIGN(E10),C10,D10)) | D11: =IF(J10,D10,IFERROR(B11-E11*(C11-B11)/(F11-E11),D10)) | E11: =LN((1+B11)/(1-B11^2)) | F11: =LN((1+C11)/(1-C11^2)) | G11: =LN((1+D11)/(1-D11^2)) | H11: =ABS(D11-D10) | I11: =IF(ISNUMBER(G11),ABS(G11),"") | J11: =IF(OR(J10,AND(ISNUMBER(H11),H11<$B$4,I11<$B$4)),TRUE,FALSE) | K11: =IF(AND(J11,NOT(J10)),"<= KONVERGEN",IF(J11,"","lanjut"))
A12: 6 | B12: =IF(J11,B11,IF(SIGN(G11)=SIGN(E11),D11,B11)) | C12: =IF(J11,C11,IF(SIGN(G11)=SIGN(E11),C11,D11)) | D12: =IF(J11,D11,IFERROR(B12-E12*(C12-B12)/(F12-E12),D11)) | E12: =LN((1+B12)/(1-B12^2)) | F12: =LN((1+C12)/(1-C12^2)) | G12: =LN((1+D12)/(1-D12^2)) | H12: =ABS(D12-D11) | I12: =IF(ISNUMBER(G12),ABS(G12),"") | J12: =IF(OR(J11,AND(ISNUMBER(H12),H12<$B$4,I12<$B$4)),TRUE,FALSE) | K12: =IF(AND(J12,NOT(J11)),"<= KONVERGEN",IF(J12,"","lanjut"))
A13: 7 | B13: =IF(J12,B12,IF(SIGN(G12)=SIGN(E12),D12,B12)) | C13: =IF(J12,C12,IF(SIGN(G12)=SIGN(E12),C12,D12)) | D13: =IF(J12,D12,IFERROR(B13-E13*(C13-B13)/(F13-E13),D12)) | E13: =LN((1+B13)/(1-B13^2)) | F13: =LN((1+C13)/(1-C13^2)) | G13: =LN((1+D13)/(1-D13^2)) | H13: =ABS(D13-D12) | I13: =IF(ISNUMBER(G13),ABS(G13),"") | J13: =IF(OR(J12,AND(ISNUMBER(H13),H13<$B$4,I13<$B$4)),TRUE,FALSE) | K13: =IF(AND(J13,NOT(J12)),"<= KONVERGEN",IF(J13,"","lanjut"))
A14: 8 | B14: =IF(J13,B13,IF(SIGN(G13)=SIGN(E13),D13,B13)) | C14: =IF(J13,C13,IF(SIGN(G13)=SIGN(E13),C13,D13)) | D14: =IF(J13,D13,IFERROR(B14-E14*(C14-B14)/(F14-E14),D13)) | E14: =LN((1+B14)/(1-B14^2)) | F14: =LN((1+C14)/(1-C14^2)) | G14: =LN((1+D14)/(1-D14^2)) | H14: =ABS(D14-D13) | I14: =IF(ISNUMBER(G14),ABS(G14),"") | J14: =IF(OR(J13,AND(ISNUMBER(H14),H14<$B$4,I14<$B$4)),TRUE,FALSE) | K14: =IF(AND(J14,NOT(J13)),"<= KONVERGEN",IF(J14,"","lanjut"))
A15: 9 | B15: =IF(J14,B14,IF(SIGN(G14)=SIGN(E14),D14,B14)) | C15: =IF(J14,C14,IF(SIGN(G14)=SIGN(E14),C14,D14)) | D15: =IF(J14,D14,IFERROR(B15-E15*(C15-B15)/(F15-E15),D14)) | E15: =LN((1+B15)/(1-B15^2)) | F15: =LN((1+C15)/(1-C15^2)) | G15: =LN((1+D15)/(1-D15^2)) | H15: =ABS(D15-D14) | I15: =IF(ISNUMBER(G15),ABS(G15),"") | J15: =IF(OR(J14,AND(ISNUMBER(H15),H15<$B$4,I15<$B$4)),TRUE,FALSE) | K15: =IF(AND(J15,NOT(J14)),"<= KONVERGEN",IF(J15,"","lanjut"))
A16: 10 | B16: =IF(J15,B15,IF(SIGN(G15)=SIGN(E15),D15,B15)) | C16: =IF(J15,C15,IF(SIGN(G15)=SIGN(E15),C15,D15)) | D16: =IF(J15,D15,IFERROR(B16-E16*(C16-B16)/(F16-E16),D15)) | E16: =LN((1+B16)/(1-B16^2)) | F16: =LN((1+C16)/(1-C16^2)) | G16: =LN((1+D16)/(1-D16^2)) | H16: =ABS(D16-D15) | I16: =IF(ISNUMBER(G16),ABS(G16),"") | J16: =IF(OR(J15,AND(ISNUMBER(H16),H16<$B$4,I16<$B$4)),TRUE,FALSE) | K16: =IF(AND(J16,NOT(J15)),"<= KONVERGEN",IF(J16,"","lanjut"))
A17: 11 | B17: =IF(J16,B16,IF(SIGN(G16)=SIGN(E16),D16,B16)) | C17: =IF(J16,C16,IF(SIGN(G16)=SIGN(E16),C16,D16)) | D17: =IF(J16,D16,IFERROR(B17-E17*(C17-B17)/(F17-E17),D16)) | E17: =LN((1+B17)/(1-B17^2)) | F17: =LN((1+C17)/(1-C17^2)) | G17: =LN((1+D17)/(1-D17^2)) | H17: =ABS(D17-D16) | I17: =IF(ISNUMBER(G17),ABS(G17),"") | J17: =IF(OR(J16,AND(ISNUMBER(H17),H17<$B$4,I17<$B$4)),TRUE,FALSE) | K17: =IF(AND(J17,NOT(J16)),"<= KONVERGEN",IF(J17,"","lanjut"))
A18: 12 | B18: =IF(J17,B17,IF(SIGN(G17)=SIGN(E17),D17,B17)) | C18: =IF(J17,C17,IF(SIGN(G17)=SIGN(E17),C17,D17)) | D18: =IF(J17,D17,IFERROR(B18-E18*(C18-B18)/(F18-E18),D17)) | E18: =LN((1+B18)/(1-B18^2)) | F18: =LN((1+C18)/(1-C18^2)) | G18: =LN((1+D18)/(1-D18^2)) | H18: =ABS(D18-D17) | I18: =IF(ISNUMBER(G18),ABS(G18),"") | J18: =IF(OR(J17,AND(ISNUMBER(H18),H18<$B$4,I18<$B$4)),TRUE,FALSE) | K18: =IF(AND(J18,NOT(J17)),"<= KONVERGEN",IF(J18,"","lanjut"))
A19: 13 | B19: =IF(J18,B18,IF(SIGN(G18)=SIGN(E18),D18,B18)) | C19: =IF(J18,C18,IF(SIGN(G18)=SIGN(E18),C18,D18)) | D19: =IF(J18,D18,IFERROR(B19-E19*(C19-B19)/(F19-E19),D18)) | E19: =LN((1+B19)/(1-B19^2)) | F19: =LN((1+C19)/(1-C19^2)) | G19: =LN((1+D19)/(1-D19^2)) | H19: =ABS(D19-D18) | I19: =IF(ISNUMBER(G19),ABS(G19),"") | J19: =IF(OR(J18,AND(ISNUMBER(H19),H19<$B$4,I19<$B$4)),TRUE,FALSE) | K19: =IF(AND(J19,NOT(J18)),"<= KONVERGEN",IF(J19,"","lanjut"))
... A26: 20 | B26: =IF(J25,B25,IF(SIGN(G25)=SIGN(E25),D25,B25)) | C26: =IF(J25,C25,IF(SIGN(G25)=SIGN(E25),C25,D25)) | D26: =IF(J25,D25,IFERROR(B26-E26*(C26-B26)/(F26-E26),D25)) | E26: =LN((1+B26)/(1-B26^2)) | F26: =LN((1+C26)/(1-C26^2)) | G26: =LN((1+D26)/(1-D26^2)) | H26: =ABS(D26-D25) | I26: =IF(ISNUMBER(G26),ABS(G26),"") | J26: =IF(OR(J25,AND(ISNUMBER(H26),H26<$B$4,I26<$B$4)),TRUE,FALSE) | K26: =IF(AND(J26,NOT(J25)),"<= KONVERGEN",IF(J26,"","lanjut"))
A28: Akar: | B28: =D26 | D28: f(akar): | E28: =G26
